model
name = main
size = 48 9 10
scale = 0.05
origin = -y
shell = Outline 0.25
material type = toon, lighting = smooth, deform = 1 1
  colors = A:#A6555F B:#C97373 C:#873555
material type = basic, lighting = smooth, roughness = 0, refractionRatio = 1, side = back
  colors = Outline:#000
voxels
337-46A-10B10A28B2-2C40-2C244-2C40-2C3-46A-2A4B4A10B5A22BA2-2C40-2C4-2A40-2A148-2A40-2A4-2C40-2C3-46A-29B18AB2-2(2A40-2A4-)2B40-2B52-2B40-2B4-2A40-2A51-46A-5B4A2B3A6B9A19B2-2A40-2A52-2A40-2A4-2C40-2C4-2A40-2A99-46A-5A9B4A30B2-2A40-2A52-2A40-2A4-2C40-2C4-2A40-2A99-46A-36B8A4B2-2(2A40-2A4-)2B40-2B52-2B40-2B4-2A40-2A51-46A-25BA2B8A12B2-2C40-2C4-2A40-2A148-2A40-2A4-2C40-2C3-46A-13A33BAB2-2C40-2C244-2C40-2C3-46A-13B24A11B337-46A-37B11A
