model
name = main
size = 18 15 8
scale = 0.05
origin = -y
material type = toon, lighting = smooth, deform = 1 1 
  colors = A:#F90 B:#777 C:#888 D:#3C3 E:#093 F:#AAA G:#963 H:#FC9 I:#555 J:#BBB K:#DDD L:#396 M:#C93 N:#F96 O:#C96 P:#111 Q:#F93 R:#FC3 S:#EEE T:#3C0 U:#693
voxels
------------------ ------------------ ------------------ ------------------ ------------------ ------------------ ------------------ ------------------ ------------------ ------------------ -------FFFJJJ----- -------FFFJJS----- ------------------ ------------------ ------------------ 
------------------ ------------------ ------------------ -------EDEDED----- ------------------ ------------------ --------A--A------ -------A----A----- -------A----A----- ------BA-A--AC---- ------BACACCAC---- ------BAAAAAAC---- -------BCCCCC----- ------------------ ------------------ 
------------------ ------------------ ------------------ -------DDEDEE----- --------DEDE------ -------ADEDDA----- -------AATDAA----- --------NNHH------ ------BRPHHPAC---- -------MAAAAM----- ------BAAAAAAC---- -------CAAAAC----- ------BBAAAACC---- --------BCCC------ ------------------ 
----G---G--G------ ----G---G--G------ ----G---H--H------ ----GH-EAEDADH---- ----G-L-EAAD--H--- --F-G--HAAAL-H---- -F--G--EAAAAE---A- FIB-G--AAAAAQ----- FIBIO-BAAAAAAC---- KIFII-BAAAAAAC---- KIF-O--CAAAAC----- -K----BAAAAAAC---- --K---BBAAAACC---- -----BB-BCCC-CC--- -----C--------F--- 
------------------ ------------------ ------------------ -------DDEDEE----- --------DEDE------ --------DEDL-----A -------AAAAAA----- -------AAAAAAA---- ------BAAAAAAC---- -------AAAAAA----- ------BAAAAAAC---- -------BAAAAC----- ------BBAAAABC---- --------BCCC------ ------------------ 
------------------ ------------------ ------------------ -------EDEDED----- ----------------A- -----------U------ --------AAAQA-A--- -------AAAAAA----- -------CABBAC----- ------BAAAAAAC---- ------BAAAAAAC---- ------BAAAAAAC---- -------BBBBBB----- ------------------ ------------------ 
------------------ ------------------ ------------------ -------------A-A-- ------------A-A--- -----------A-A---- ---------AA-A----- --------A--A------ --------B--B------ -------BABBAB----- -------BAAAAB----- -------BBBBBB----- ------------------ ------------------ ------------------ 
------------------ ------------------ ------------------ ------------------ ------------------ ------------------ ------------------ ------------------ --------B--B------ --------BBBB------ --------BBBB------ ------------------ ------------------ ------------------ ------------------ 
