model
name = main
size = 14 30 7
scale = 0.05
origin = -y
material type = toon, lighting = smooth, deform = 1 1 
  colors = A:#F2AE99 B:#FFF C:#A6555F D:#873555 E:#C97373 F:#4A3052
voxels
--CCC----CCC-- -------------- -------------- -------------- -------------- -------------- -------------- -------------- -------------- -------------- -------------- -------------- -------------- -------------- -------------- -------------- -------------- -------------- -------------- -------------- -------------- -------------- -------------- -------------- -------------- -------------- -------------- -------------- -------------- -------------- 
--CAC----CAC-- --CCC----CCC-- -------------- -------------- -------------- -------------- -------------- -------------- -------------- -------------- -------------- -------------- -------------- -------------- -------------- -------------- -------------- -------------- -----BBBB----- ----BBBBBB---- ----BBBBBB---- ----BBBBBB---- -------------- -------------- -------------- -------------- -------------- -------------- -------------- -------------- 
--CAC----CAC-- --CAC----CAC-- --DDD----DDD-- -------------- -------------- -------------- -------------- -------------- -------------- -------------- -------------- -------------- ------CC------ ------CC------ ------BB------ ------BB------ ------BB------ ------BB------ ----BBAABB---- ----BAAAAB---- ----BAAAAB---- ----BAAAAB---- ----BBBBBB---- -------------- -----AAAA----- -----AAAA----- -----AAAA----- -----FAAF----- -----FAAF----- -----AAAA----- 
--CAC----CAC-- --CAC----CAC-- --DAD----DAD-- --DDD----DDD-- --DDD----DDD-- ---D------D--- --CCC----CCC-- --CCC----CCC-- --CCC----CCC-- --CCC----CCC-- --CCC-CC-CCC-- ---C-CCCC-C--- ---CCCAACCC--- ---ECEAAECE--- -----BAAB----- -----BAAB----- -----BAAB----- -----BAAB----- ----BAAAAB---- ----BAAAAB---- ----BAAAAB---- --B-BAAAAB-B-- --BBBBBBBBBB-- ---B------B--- -----AAAA----- -----AAAA----- -----AAAA----- -----AAAA----- -----AAAA----- -----AAAA----- 
--CAC----CAC-- --CCC----CCC-- --DDD----DDD-- --DDD----DDD-- --DDD----DDD-- ---D------D--- --CCC----CCC-- --CCC----CCC-- --CCC----CCC-- --CCC----CCC-- --CCC-CC-CCC-- ---C-CCCC-C--- A--CCCCCCCC--A A--CECAACEC--A A----BAAB----A A----BAAB----A AA---BAAB---AA -A---BAAB---A- -AA-BAAAAB-AA- --A-BAAAAB-A-- --A-BAAAAB-A-- -BB-BAAAAB-BB- --BBBBAABBBB-- ---B--AA--B--- -----AAAA----- -----AAAA----- -----AAAA----- -----AAAA----- -----AAAA----- -----AAAA----- 
---C------C--- -------------- -------------- -------------- -------------- -------------- -------------- -------------- -------------- -------------- -------------- -------------- -------------- ------EE------ ------BB------ ------BB------ ------BB------ ------BB------ ----BBAABB---- ----BBAABB---- ----BBAABB---- --B-BBAABB-B-- --BBBBAABBBB-- ---B--AA--B--- ------AA------ ------AA------ -----AAAA----- -----AAAA----- -----AAAA----- -----AAAA----- 
-------------- -------------- -------------- -------------- -------------- -------------- -------------- -------------- -------------- -------------- -------------- -------------- -------------- -------------- -------------- -------------- -------------- -------------- ------BB------ ------BB------ ------BB------ ------BB------ ------BB------ -------------- -------------- -------------- -----AAAA----- -----AAAA----- -----AAAA----- -----AAAA----- 
