model
name = main
size = 21
scale = 0.05
origin = -y
shell = Outline 0.25
material type = toon, lighting = smooth, deform = 1 1
  colors = A:#FC9
material type = basic, lighting = smooth, roughness = 0, refractionRatio = 1, side = back
  colors = Outline:#000
voxels
--------------------- --------------------- --------------------- --------------------- --------------------- --------------------- --------------------- --AAAAA-------AAAAA-- --------------------- --------------------- --------------------- --------------------- --------------------- -AAAAAAAAAAAAAAAAAAA- --A-A-A-A-A-A-A-A-A-- --------------------- AAAAA-----------AAAAA AAAAA-----------AAAAA A-A-A-----------A-A-A AAAAA-----------AAAAA A-A-A-----------A-A-A 
--AAAAA-------AAAAA-- --AAAAA-------AAAAA-- --AAAAA-------AAAAA-- --AAAAA-------AAAAA-- --AAAAA-------AAAAA-- --AAAAA-------AAAAA-- --AAAAA-------AAAAA-- -AAAAAAA-----AAAAAAA- --AAAAA-------AAAAA-- --AAAAAA-----AAAAAA-- --AAAAAAA---AAAAAAA-- --A-A-AAAAAAAAA-A-A-- --AAAAAAAAAAAAAAAAA-- -AAA-------------AAA- -AAA-------------AAA- --A---------------A-- AAAAA-----------AAAAA A---A-----------A---A --------------------- A---A-----------A---A --------------------- 
--AAAAA-------AAAAA-- --AAAAA-------AAAAA-- --AAAAA-------AAAAA-- --AAAAA-------AAAAA-- --AAAAA-------AAAAA-- --AAAAA-------AAAAA-- --AAAAA-------AAAAA-- -AAAAAAA-----AAAAAAA- --AAAAA-------AAAAA-- --AAAAAAA---AAAAAAA-- --AAAAAAAAAAAAAAAAA-- --AAAAAAAAAAAAAAAAA-- --AAAAAAAAAAAAAAAAA-- -AAA-------------AAA- -AAA-------------AAA- -AAA-------------AAA- AAAAA-----------AAAAA A---A-----------A---A A---A-----------A---A A---A-----------A---A A---A-----------A---A 
--AAAAA-------AAAAA-- --AAAAA-------AAAAA-- --AAAAA-------AAAAA-- --AAAAA-------AAAAA-- --AAAAA-------AAAAA-- --AAAAA-------AAAAA-- --AAAAA-------AAAAA-- -AAAAAAA-----AAAAAAA- --AAAAA-------AAAAA-- --AAAAAAAAAAAAAAAAA-- --AAAAAAAAAAAAAAAAA-- ---AAAAAAAAAAAAAAA--- --AAAAAAAAAAAAAAAAA-- -AAA-------------AAA- -AAA-------------AAA- --A---------------A-- AAAAA-----------AAAAA A---A-----------A---A --------------------- A---A-----------A---A --------------------- 
---AAAA-------AAAA--- ---AAAA-------AAAA--- ---AAAA-------AAAA--- ---AAAA-------AAAA--- --AAAAA-------AAAAA-- --AAAAA-------AAAAA-- --AAAAA-------AAAAA-- -AAAAAAA-----AAAAAAA- --AAAAA-------AAAAA-- --AAAAAAAAAAAAAAAAA-- --AAAAAAAAAAAAAAAAA-- --AAAAAAAAAAAAAAAAA-- --AAAAA-AAAAA-AAAAA-- -A--AAAAAAAAAAAAA--A- ----A-A-A-A-A-A-A---- --------------------- AAAAA-----------AAAAA AAAAA-----------AAAAA A-A-A-----------A-A-A AAAAA-----------AAAAA A-A-A-----------A-A-A 
----A-----------A---- ----A-----------A---- ----A-----------A---- ----A-----------A---- --AAA-----------AAA-- --AAA-----------AAA-- --AAA-----------AAA-- -AAAA-----------AAAA- --AAA-----------AAA-- --AAA-----------AAA-- --AAA-----------AAA-- ---AA-----------AA--- --AAA-----------AAA-- -A--A-----------A--A- -A-----------------A- --------------------- --------------------- --------------------- --------------------- --------------------- --------------------- 
---AA-----------AA--- ---AA-----------AA--- ---AA-----------AA--- ---AA-----------AA--- --AAA-----------AAA-- --AAA-----------AAA-- --AAA-----------AAA-- -AAAA-----------AAAA- --AAA-----------AAA-- --AAA-----------AAA-- --AAA-----------AAA-- --AAA-----------AAA-- --AAA-----------AAA-- -A--A-----------A--A- ----A-----------A---- --------------------- --------------------- --------------------- --------------------- --------------------- --------------------- 
--AAA-----------AAA-- --AAA-----------AAA-- --AAA-----------AAA-- --AAA-----------AAA-- --AAA-----------AAA-- --AAA-----------AAA-- --AAA-----------AAA-- -AAAA-----------AAAA- --AAA-----------AAA-- --AAA-----------AAA-- --AAA-----------AAA-- ---AA-----------AA--- --AA-------------AA-- -A--A-----------A--A- -A-----------------A- --------------------- --------------------- --------------------- --------------------- --------------------- --------------------- 
--AAA-----------AAA-- --AAA-----------AAA-- --AAA-----------AAA-- --AAA-----------AAA-- --AAA-----------AAA-- --AAA-----------AAA-- --AAA-----------AAA-- -AAAA-----------AAAA- --AAA-----------AAA-- --AAA-----------AAA-- --AAA-----------AAA-- --AAA-----------AAA-- --AAA-----------AAA-- -A--A-----------A--A- ----A-----------A---- --------------------- --------------------- --------------------- --------------------- --------------------- --------------------- 
--AAA-----------AAA-- --AAA-----------AAA-- --AAA-----------AAA-- --AAA-----------AAA-- --AAA-----------AAA-- --AAA-----------AAA-- --AAA-----------AAA-- -AAAA-----------AAAA- --AAA-----------AAA-- --AAA-----------AAA-- --AAA-----------AAA-- ---AA-----------AA--- --AAA-----------AAA-- -A--A-----------A--A- -A-----------------A- --------------------- --------------------- --------------------- --------------------- --------------------- --------------------- 
--AAA-----------AAA-- --AAA-----------AAA-- --AAA-----------AAA-- --AAA-----------AAA-- --AAA-----------AAA-- --AAA-----------AAA-- --AAA-----------AAA-- -AAAA-----------AAAA- --AAA-----------AAA-- --AAA-----------AAA-- --AAA-----------AAA-- --AAA-----------AAA-- --AAA-----------AAA-- -A--A-----------A--A- ----A-----------A---- --------------------- --------------------- --------------------- --------------------- --------------------- --------------------- 
--AAA-----------AAA-- --AAA-----------AAA-- --AAA-----------AAA-- --AAA-----------AAA-- --AAA-----------AAA-- --AAA-----------AAA-- --AAA-----------AAA-- -AAAA-----------AAAA- --AAA-----------AAA-- --AAA-----------AAA-- --AAA-----------AAA-- ---AA-----------AA--- --AAA-----------AAA-- -A--A-----------A--A- -A-----------------A- --------------------- --------------------- --------------------- --------------------- --------------------- --------------------- 
--AAA-----------AAA-- --AAA-----------AAA-- --AAA-----------AAA-- --AAA-----------AAA-- --AAA-----------AAA-- --AAA-----------AAA-- --AAA-----------AAA-- -AAAA-----------AAAA- --AAA-----------AAA-- --AAA-----------AAA-- --AAA-----------AAA-- --AAA-----------AAA-- --AAA-----------AAA-- -A--A-----------A--A- ----A-----------A---- --------------------- --------------------- --------------------- --------------------- --------------------- --------------------- 
--AAA-----------AAA-- --AAA-----------AAA-- --AAA-----------AAA-- --AAA-----------AAA-- --AAA-----------AAA-- --AAA-----------AAA-- --AAA-----------AAA-- -AAAA-----------AAAA- --AAA-----------AAA-- --AAA-----------AAA-- --AAA-----------AAA-- ---AA-----------AA--- --AA-------------AA-- -A--A-----------A--A- -A-----------------A- --------------------- --------------------- --------------------- --------------------- --------------------- --------------------- 
---AA-----------AA--- ---AA-----------AA--- ---AA-----------AA--- ---AA-----------AA--- --AAA-----------AAA-- --AAA-----------AAA-- --AAA-----------AAA-- -AAAA-----------AAAA- --AAA-----------AAA-- --AAA-----------AAA-- --AAA-----------AAA-- --AAA-----------AAA-- --AAA-----------AAA-- -A--A-----------A--A- ----A-----------A---- --------------------- --------------------- --------------------- --------------------- --------------------- --------------------- 
----A-----------A---- ----A-----------A---- ----A-----------A---- ----A-----------A---- --AAA-----------AAA-- --AAA-----------AAA-- --AAA-----------AAA-- -AAAA-----------AAAA- --AAA-----------AAA-- --AAA-----------AAA-- --AAA-----------AAA-- ---AA-----------AA--- --AAA-----------AAA-- -A--A-----------A--A- -A-----------------A- --------------------- --------------------- --------------------- --------------------- --------------------- --------------------- 
---AAAA-------AAAA--- ---AAAA-------AAAA--- ---AAAA-------AAAA--- ---AAAA-------AAAA--- --AAAAA-------AAAAA-- --AAAAA-------AAAAA-- --AAAAA-------AAAAA-- -AAAAAAA-----AAAAAAA- --AAAAA-------AAAAA-- --AAAAAAAAAAAAAAAAA-- --AAAAAAAAAAAAAAAAA-- --AAAAAAAAAAAAAAAAA-- --AAAAA-AAAAA-AAAAA-- -A--AAAAAAAAAAAAA--A- ----A-A-A-A-A-A-A---- --------------------- AAAAA-----------AAAAA AAAAA-----------AAAAA A-A-A-----------A-A-A AAAAA-----------AAAAA A-A-A-----------A-A-A 
--AAAAA-------AAAAA-- --AAAAA-------AAAAA-- --AAAAA-------AAAAA-- --AAAAA-------AAAAA-- --AAAAA-------AAAAA-- --AAAAA-------AAAAA-- --AAAAA-------AAAAA-- -AAAAAAA-----AAAAAAA- --AAAAA-------AAAAA-- --AAAAAAAAAAAAAAAAA-- --AAAAAAAAAAAAAAAAA-- ---AAAAAAAAAAAAAAA--- --AAAAAAAAAAAAAAAAA-- -AAA-------------AAA- -AAA-------------AAA- --A---------------A-- AAAAA-----------AAAAA A---A-----------A---A --------------------- A---A-----------A---A --------------------- 
--AAAAA-------AAAAA-- --AAAAA-------AAAAA-- --AAAAA-------AAAAA-- --AAAAA-------AAAAA-- --AAAAA-------AAAAA-- --AAAAA-------AAAAA-- --AAAAA-------AAAAA-- -AAAAAAA-----AAAAAAA- --AAAAA-------AAAAA-- --AAAAAAA---AAAAAAA-- --AAAAAAAAAAAAAAAAA-- --AAAAAAAAAAAAAAAAA-- --AAAAAAAAAAAAAAAAA-- -AAA-------------AAA- -AAA-------------AAA- -AAA-------------AAA- AAAAA-----------AAAAA A---A-----------A---A A---A-----------A---A A---A-----------A---A A---A-----------A---A 
--AAAAA-------AAAAA-- --AAAAA-------AAAAA-- --AAAAA-------AAAAA-- --AAAAA-------AAAAA-- --AAAAA-------AAAAA-- --AAAAA-------AAAAA-- --AAAAA-------AAAAA-- -AAAAAAA-----AAAAAAA- --AAAAA-------AAAAA-- --AAAAAA-----AAAAAA-- --AAAAAAA---AAAAAAA-- --A-A-AAAAAAAAA-A-A-- --AAAAAAAAAAAAAAAAA-- -AAA-------------AAA- -AAA-------------AAA- --A---------------A-- AAAAA-----------AAAAA A---A-----------A---A --------------------- A---A-----------A---A --------------------- 
--------------------- --------------------- --------------------- --------------------- --------------------- --------------------- --------------------- --AAAAA-------AAAAA-- --------------------- --------------------- --------------------- --------------------- --------------------- -AAAAAAAAAAAAAAAAAAA- --A-A-A-A-A-A-A-A-A-- --------------------- AAAAA-----------AAAAA AAAAA-----------AAAAA A-A-A-----------A-A-A AAAAA-----------AAAAA A-A-A-----------A-A-A