size = 40 17 40
scale = 0.025
rotation = -6 0 0
position = 0 -0.03 0
origin = -y
material lighting = smooth, roughness = 0.2, metalness = 0.5, deform = 2 1
  colors = D:#FF6600 B:#0066FF A:#EE0000 C:#777777 F:#555555 E:#111111
voxels
259-9(2A38-)2A310-18A23-16A30-4A37-7(2A38-)A270-20A21-18A29-4A37-7(2A38-)2A158-2A109-20A21-18A29-4A37-6(2A38-)2A198-2A38-2A70-18A23-16A30-4A37-5(2A38-)2A198-2E2(38-2A)71-16A25-14A31-4A37-4(2A38-)2A238-2E2(38-2A)38-2D32-14A27-12A32-4A37-3(2A38-)2A398-2D33-12A32-4A36-7(4A596-2(4A36-))4A557-2A37-4A35-6A35-4A37-2A517-4A35-2(6A34-)6A35-4A516-4A35-2(6A34-)6A35-4A476-5(4A35-6A33-2(8A32-)8A33-6A35-4A436-)4A35-6A33-2(8A32-)8A33-6A35-4A309-2A14-2A109-4A19-16B6A16B17-2(2A4E2A32-)2A4E2A33-A4EA35-4E59-13B12-13B212-2A14-2A22-2A14-2A69-4A18-17B6A17B4-C11-2A4E2(2A11-C8-C11-2A4-)2A11-C8-C12-A4-A12-2(C8-C30-)C4-16B8-16B172-E14-E23-2(2A14-2A22-)2A14-2A29-4A18-17B6A17B16-2A4E2(2A32-2A4-)2A33-A4-A97-40B172-E14-E23-2A14-2A22-2A14C2A22-2A2-2D6-2D2-2A27-2D4A2D16-17B6A17B16-2(2A4-2A32-)2A4-2A33-A-2C-A36-2C59-40B172-E14-E23-2A14-2A22-2A14-2A69-4A18-17B6A17B16-2(2A4-2A32-)2A4-2A33-A-2C-A97-40B338-4A18-17B6A17B4-2(C11-2A4-2A11-C8-)C10-C2A4-2AC10-C8-C9-3C6A3C9-2(C8-)2C3-4A3-2C3(8-C)12-C8-C4-40B338-4A19-16B6A16B17-2(8A32-)8A33-6A35-4A59-38B339-3(4A35-6A33-2(8A32-)8A33-6A35-4A436-)4A35-2A2F2A33-2A4F2A32-A6FA32-2A4F2A33-2A2F2A35-4A436-4A35-2A2-2A33-2A4-2A32-A2-2F2-A32-2A4-2A33-2A2-2A35-4A557-2F597-4B29-7D4B7D22-8D2F8D29-4B556-3(4B36-)4B597-2B38-2B379-