size = 10 10 10
shape = box // sphere
scale = 0.100
origin = -y
wireframe = false
clamp = none
ao = 3 0.5
rotation = 0 160 0
material lighting = flat, fade = true
  colors = A:#FFF B:#FFF
voxels
AAAAAAAAAA AAAAAAAAAA AA------AA AA------AA AA------AA AA------AA AA------AA AA------AA AAAAAAAAAA AAAAAAAAAA 
AAAAAAAAAA AAAAAAAAAA AAAAAAAAAA AAAAAAAAAA AAAAAAAAAA AAAAAAAAAA AAAAAAAAAA AAAAAAAAAA AAAAAAAAAA AAAAAAAAAA 
AAAAAAAAAA AAAAAAAAAA -AAAAAA--- -AAAAAA--- AAAAAAA--- -AAAAAAAAA AAAAAAAA-- -AAAAAAA-- AAAAAAAAAA AAAAAAAAAA 
AAAAAAAAAA AAAAAAAAAA -AAAAAA--- -AAAAAA--- AAAAAAA--- -AAAAAAAAA AAAAAAAAAA AAAAAAAAAA AAAAAAAAAA AAAAAAAAAA 
AAAA--AAAA AAAA--AAAA AAAA--A--- AAAA--A--- AAAA--A--- -AAA--AAAA AAAA--AAAA -AAA--A--- AAAA--AAAA AAAA--AAAA 
AAAA--AAAA AAAA--AAAA -AAA--AAAA -AAA--AAAA -AAA--AAAA AAAA--A--- AAAA--AAAA -AAA--A--- AAAA--AAAA AAAA--AAAA 
AAAAAAAAAA AAAAAAAAAA -AAAAAAA-- -AAAAAAA-- -AAAAAAAAA AAAAAAA--- AAAAAAAAAA AAAAAAAAAA AAAAAAAAAA AAAAAAAAAA 
AAAAAAAAAA AAAAAAAAAA -AAAAAAA-- -AAAAAAA-- -AAAAAAAAA AAAAAAA--- -AAAAAAAAA -AAAAAA--- AAAAAAAAAA AAAAAAAAAA 
AAAAAAAAAA AAAAAAAAAA AAAAAAAAAA AAAAAAAAAA AAAAAAAAAA AAAAAAAAAA AAAAAAAAAA AAAAAAAAAA AAAAAAAAAA AAAAAAAAAA 
AAAAAAAAAA AAAAAAAAAA AA------AA AA-AAAA-AA AA-AAAA-AA AA-AAAA-AA AA-AAAA-AA AA------AA AAAAAAAAAA AAAAAAAAAA