model
size     = 20 18 20
scale    = 0.05
origin   = -y
rotation = 0 -45 0
material lighting = both, roughness = 0.2, metalness = 1, deform =  5, clamp = -x 
  colors = S:#800
material lighting = flat, roughness = 1.0,                deform =  2, scatter = 0.2
  colors = V:#080
material lighting = both, roughness = 0.0, metalness = 1.0, opacity = 0.7, deform = 10, clamp = y
  colors = O:#8CF
material lighting = flat, roughness = 0.5
  colors = X:#138
voxels
-----------VV------- ----------VVVV------ ----------VVVV------ ---------VVVVVV----- ---------VVVVVV----- --------VVVVVVVV---- --------VVV--VVV---- -------VVVV--VVVV--- -------VVV----VVV--- ------VVVV----VVVV-- ------VVV------VVV-- -----VVVV------VVVV- -----VVV--------VVV- ----VVVV--------VVVV ----VVV----------VVV ----VVV----------VVV ----VVV----------VVV ----VVV----------VVV 
-----------VV------- ----------VVVV------ ----------VVVV------ ---------VVVVVV----- ---------VVVVVV----- --------VVVVVVVV---- --------VVV--VVV---- -------VVVV--VVVV--- -------VVV----VVV--- ------VVVV----VVVV-- ------VVV------VVV-- -----VVVV------VVVV- -----VVV--------VVV- ----VVVV--------VVVV ----VVV----------VVV ----VVV----------VVV ----VVV----------VVV ----VVV----------VVV 
-----------VV------- ----------VVVV------ ----------VVVV------ ---------VVVVVV----- ---------VVVVVV----- --------VVVVVVVV---- --------VVV--VVV---- -------VVVV--VVVV--- -------VVV----VVV--- ------VVVV----VVVV-- ------VVV------VVV-- -----VVVV------VVVV- -----VVV--------VVV- ----VVVV--------VVVV ----VVV----------VVV ----VVV----------VVV ----VVV----------VVV ----VVV----------VVV 
-------------------- -------------------- -------------------- -------------------- -------------------- -------------------- -------------------- -------------------- -------------------- -------------------- -------------------- -------------------- -------------------- -------------------- -------------------- -------------------- -------------------- -------------------- 
-------------------- -------------------- -------------------- -------------------- -------------------- -------------------- -------------------- -------------------- ---------OOOOOO----- ---------OOOOOO----- -------------------- -------------------- -------------------- -------------------- -------------------- -------------------- -------------------- -------------------- 
-------------------- -------------------- -------------------- SSS----------------- SSS----------------- SSS----------------- SSS----------------- SSS----------------- -------OOOOOOOOOO--- -------OOOOOOOOOO--- -------------------- -------------------- -------------------- -------------------- -------------------- SSS----------------- SSS----------------- SSS----------------- 
-------------------- -------------------- SSS----------------- SSS----------------- SSS----------------- SSS----------------- SSS----------------- SSS----------------- SSS---OOOOOOOOOOOO-- ------OOOOOOOOOOOO-- -------------------- -------------------- -------------------- -------------------- -------------------- SSS----------------- SSS----------------- SSS----------------- 
---------------XX--- SSS------------XX--- SSS------------XX--- SSS----------------- SSS----------------- SSS----------------- SSS----------------- SSS----------------- SSS--OOOOO----OOOOO- SSS--OOOOO----OOOOO- -------------------- -------------------- -------------------- -------------------- -------------------- SSS------------XX--- SSS------------XX--- SSS------------XX--- 
SSS------------XX--- SSS------------XX--- SSS------------XX--- SSS----------------- SSS----------------- SSS----------------- SSS----------------- SSS----------------- SSS--OOOO------OOOO- SSS--OOOO------OOOO- SSS----------------- -------------------- -------------------- -------------------- -------------------- SSS------------XX--- SSS------------XX--- SSS------------XX--- 
SSS----------------- SSS----------------- SSS----------------- SSS----------XX----- -------------XX----- -------------XX----- -------------XX----- SSS----------------- SSS-OOOO--------OOOO SSS-OOOO--------OOOO SSS----------------- -------------XX----- -------------XX----- -------------XX----- -------------XX----- SSS----------------- SSS----------------- SSS----------------- 
SSS----------------- SSS----------------- SSS----------------- -------------XX----- -------------XX----- -------------XX----- -------------XX----- -------------------- SSS-OOO----------OOO SSS-OOO----------OOO SSS----------------- -------------XX----- -------------XX----- -------------XX----- -------------XX----- SSS----------------- SSS----------------- SSS----------------- 
SSS----------------- SSS----------------- SSS----------------- -------------------- -------------------- -------------------- -------------------- -----------XX------- SSS-OOO----XX----OOO SSS-OOO----XX----OOO SSS--------XX------- -------------------- -------------------- -------------------- -------------------- SSS----------------- SSS----------------- SSS----------------- 
SSS----------------- SSS----------------- SSS----------------- -------------------- -------------------- -------------------- -------------------- -----------XX------- SSS-OOO----XX----OOO SSS-OOO----XX----OOO SSS--------XX------- -------------------- -------------------- -------------------- -------------------- SSS----------------- SSS----------------- SSS----------------- 
SSS----------------- SSS----------------- SSS----------------- ---------XX--------- ---------XX--------- ---------XX--------- ---------XX--------- -------------------- SSS-OOO----------OOO SSS-OOO----------OOO SSS----------------- ---------XX--------- ---------XX--------- ---------XX--------- ---------XX--------- SSS----------------- SSS----------------- SSS----------------- 
SSS----------------- SSS----------------- SSS----------------- ---------XX--------- ---------XX--------- ---------XX--------- ---------XX--------- -------------------- SSS-OOOO--------OOOO SSS-OOOO--------OOOO SSS----------------- SSS------XX--------- ---------XX--------- ---------XX--------- SSS------XX--------- SSS----------------- SSS----------------- SSS----------------- 
SSS----XX----------- SSS----XX----------- SSS----XX----------- -------------------- -------------------- -------------------- -------------------- -------------------- SSS--OOOO------OOOO- SSS--OOOO------OOOO- SSS----------------- SSS----------------- SSS----------------- SSS----------------- SSS----------------- SSS----XX----------- SSS----XX----------- SSS----XX----------- 
SSS----XX----------- SSS----XX----------- SSS----XX----------- -------------------- -------------------- -------------------- -------------------- -------------------- -----OOOOO----OOOOO- SSS--OOOOO----OOOOO- SSS----------------- SSS----------------- SSS----------------- SSS----------------- SSS----------------- SSS----XX----------- SSS----XX----------- -------XX----------- 
SSS----------------- SSS----------------- SSS----------------- -------------------- -------------------- -------------------- -------------------- -------------------- ------OOOOOOOOOOOO-- ------OOOOOOOOOOOO-- SSS----------------- SSS----------------- SSS----------------- SSS----------------- SSS----------------- SSS----------------- -------------------- -------------------- 
SSS----------------- SSS----------------- SSS----------------- -------------------- -------------------- -------------------- -------------------- -------------------- -------OOOOOOOOOO--- -------OOOOOOOOOO--- -------------------- SSS----------------- SSS----------------- SSS----------------- SSS----------------- -------------------- -------------------- -------------------- 
-------------------- -------------------- -------------------- -------------------- -------------------- -------------------- -------------------- -------------------- ---------OOOOOO----- ---------OOOOOO----- -------------------- -------------------- -------------------- -------------------- -------------------- -------------------- -------------------- --------------------