model
name = main
size = 118 60 121
scale = 0.05
origin = -y
material type = toon, lighting = smooth, deform = 1 1 
  colors = A:#818181 B:#FF5B5E C:#FF4928 D:#98D25E
voxels
4(116A2-45(A117-)116A2-116A1418-)116A2-40(A117-)A116-2A116-120A117-A117-116A2-116A1418-116A2-20(15A103-)6(42A76-)14(A117-)A116-2A117-A39-A3-A73-2(A117-)116A2-116A1418-116A2-4(15A6-A17-A8-A17-A7-A17-A25-)15A6-19A8-19A7-19A25-15(15A103-)2(42A76-4(11A107-)42A76-14(A117-)A116-2A117-A39-A3-A73-2(A117-)116A2-116A1418-116A2-20(15A103-))42A76-4(11A107-)42A76-14(A117-)119A3(117-A39-A3-A73-2(A117-)116A2-116A1418-116A2-20(15A103-)42A76-4(11A107-)42A76-14(A117-)A116-2A)117-A39-A3-A73-2(A117-)116A2-116A1418-116A2-20(15A103-)42A76-4(11A107-)42A76-14(A117-)119A2(117-A39-A3-A73-2(A117-)116A2-116A1418-116A2-20(15A103-)42A76-4(11A107-)42A76-14(A117-)A116-2A)117-A39-A3-A73-2(A117-)116A2-116A1418-116A2-20(15A103-)6(42A76-)14(A117-)A116-2A117-A39-A3-A73-2(A117-)116A2-116A1418-116A2-40(A117-)119A3(117-A39-A3-A73-2(A117-)116A2-116A1418-116A2-40(A117-)A116-2A)117-A39-A3-A73-2(A117-)116A2-116A1418-116A2-5(A117-)A51-3A63-34(A117-)A116-2A117-A39-A3-A73-2(A117-)116A2-116A1418-116A2-5(A52-A64-)A51-A-A63-34(A117-)A116-2A117-A39-A3-A73-2(A117-)116A2-116A1418-116A2-5(A117-)A51-3A63-34(A117-)A116-2A117-A39-A3-A73-2(A117-)116A2-116A1418-116A2-3(A117-)A77-3A37-36(A117-)A116-2A117-A39-A3-A73-2(A117-)116A2-116A1418-116A2-3(A78-A38-)A77-A-A37-36(A117-)A39-A3-A72-2A2(39-A3-A73-A)117-A117-116A2-116A1418-116A2-3(27A91-)27A51-3A37-6(27A91-)30(A117-)A39-A3-A72-2A2(39-A77-A)117-A117-116A2-116A1418-116A2-10(27A91-)3(A24-A92-)2(26A2(92-A24-A)92-)26A92-20(A117-)A39-A3-A72-2A3(117-A)117-116A2-116A1418-116A2-10(27A91-)3(A117-)3(A24-A92-2(A117-))18(A117-)A39-A3-A72-2A3(117-A)117-116A2-116A1418-116A2-9(27A91-)27A79-3A9-3(A117-)3(A24-A92-2(A117-))18(A117-)A39-A3-A72-2A3(117-A)117-116A2-116A1418-116A2-9(27A80-A10-)27A79-A-A9-3(A117-)3(A24-A92-2(A117-))18(A117-)A39-A3-A72-2A3(117-A)117-116A2-116A1418-116A2-9(27A91-)27A79-3A9-2(3(A117-)3(A24-A92-2(A117-))18(A117-)A39-A3-A72-2A3(117-A)117-116A2-116A1418-116A2-10(27A91-))3(A117-)3(A24-A92-2(A117-))18(A117-)A39-A3-A72-2A3(117-A)5-5A107-54A9-32A9-12A2-116A1418-116A2-10(27A91-)3(A117-)3(A24-A92-2(A117-))18(A117-)A39-A3-A72-2A3(117-A)5-A3-A107-54A-7A-32A-7A-12A2-116A1418-116A2-10(27A91-)3(A117-)3(A24-A92-2(A117-))18(A117-)A39-A3-A72-2A3(117-A)5-A3-A107-54A-A-3A-A-32A-A-3A-A-12A2-116A1418-116A2-10(27A91-)3(A117-)3(A24-A92-2(A117-))18(A117-)A39-A3-A72-2A3(117-A)5-A3-A107-54A-7A-32A-7A-12A2-116A1418-116A2-10(27A91-)3(A4-13A100-)3(A4-13A7-A92-2(A4-13A100-))13(A4-13A100-)5(A117-)A39-A3-A72-2A3(117-A)5-5A107-54A-A-3A-A-32A-A-3A-A-12A2-116A1418-116A2-10(27A91-)3(A4-2A9-A101-)3(A4-2A9-A8-A92-2(A4-2A9-A101-))5(A4-2A9-A101-)3(A4-2A111-A4-2A9-A101-)A4-2A111-A4-13A100-5(A117-)A39-A3-A72-2A3(117-A)117-54A-7A-32A-7A-12A2-116A1418-116A2-4(27A49-16A26-)4(27A49-5A4-7A26-)27A49-16A26-27A91-3(A4-2A9-A101-)3(A4-2A9-A8-A92-2(A4-2A9-A101-))5(A4-2A9-A101-)3(A4-2A111-A4-2A9-A101-)A4-2A111-A4-13A100-5(A117-)A39-A3-A72-2A3(117-A)117-54A9-32A9-12A2-116A1418-116A2-8(27A49-16A26-)27A49-8A6-2A26-27A91-10(A4-2A9-A8-A92-)7(A4-2A9-A101-)3(A4-2A111-A4-2A9-A101-)A4-2A111-A4-13A100-5(A117-)A39-A3-A72-2A3(117-A)117-116A2-116A1418-116A2-2(41A35-16A26-)2(38A38-16A26-)2(35A41-16A26-)2(32A44-16A26-)5(29A47-8A6-2A26-29A89-17(A4-2A9-A101-)3(A4-2A111-A4-2A9-A101-)A4-2A111-A4-13A100-5(A117-)A39-A3-A72-2A3(117-A)117-116A2-116A1418-116A2-2(41A35-16A26-)38A38-16A26-38A38-2(15A27-35A41-)2(15A27-32A44-)16A26-)29A47-16A26-29A89-17(A4-2A9-A101-)3(A4-2A111-A4-2A9-A101-)A4-2A111-A4-13A100-5(A117-)A39-A3-A72-2A3(117-A)117-116A2-116A1418-116A2-2(41A35-16A26-)2(38A38-16A26-)2(35A41-16A26-)2(32A44-16A26-)29A47-16A26-29A89-25(A4-13A100-)5(A117-)A39-A3-A72-2A3(117-A)117-116A2-116A1418-116A2-2(41A35-16A26-)2(38A38-16A26-)2(35A41-16A26-)2(32A44-16A26-)29A47-16A26-29A89-30(A117-)A39-A3-A72-2A3(117-A)117-116A2-116A1418-116A2-2(41A35-16A26-)2(38A38-16A26-)2(35A41-16A26-)2(32A44-16A26-)29A47-16A26-29A89-26(A117-)A74-3A40-3(A117-)A39-A3-A72-2A3(117-A)117-116A2-116A1418-116A2-2(41A35-16A26-)2(38A38-16A26-)2(35A41-16A26-)2(32A44-16A26-)29A47-16A26-29A89-26(A117-)A74-A-A40-3(A75-A41-)A39-A3-A31-A40-2A75-A41-49A27-2(A41-A75-)A41-116A2-116A1418-116A2-2(41A35-16A26-)2(38A38-16A26-)2(35A41-16A26-)2(32A44-16A26-)29A47-16A26-29A89-26(A117-)A74-3A40-3(A117-)A39-A3-A72-2A117-A47-A69-2(A117-)116A2-116A1418-116A2-2(41A35-16A26-)2(38A38-16A26-)2(35A41-16A26-)2(32A44-16A26-)29A47-16A26-29A89-2(30(A117-)A39-A3-A72-2A117-A47-A69-2(A117-)116A2-116A1418-116A2-2(41A77-)2(38A80-)2(35A83-)2(32A86-)2(29A89-))28(A117-)A87-3A27-A117-A39-A3-A72-2A117-A47-A69-2(A117-)116A2-116A1418-116A2-2(41A77-)2(38A80-)2(35A83-)2(32A86-)2(29A89-)28(A117-)A87-A-A27-A88-A28-A39-A3-A44-A27-2A88-A28-A47-A40-2(A28-A88-)A28-116A2-116A1418-116A2-10(27A91-)10(A24-A92-)18(A117-)A87-3A27-A117-A39-A3-A72-2A65-3A49-A47-A69-2(A117-)116A2-116A1418-116A2-10(27A91-)3(A117-)3(A24-A92-2(A117-))18(A117-)A39-A3-A72-2A65-A-A49-A47-A18-2(A50-A66-)A50-116A2-116A1418-116A2-10(27A91-)3(A117-)3(A24-A92-2(A117-))18(A117-)A39-A3-A72-2A65-3A49-2(A47-A69-2(A117-)116A2-116A1418-116A2-10(27A91-)3(A117-)3(A24-A92-2(A117-))18(A117-)A39-A3-A72-2A117-)A47-A69-2(A117-)116A2-116A1418-116A2-10(27A91-)3(A117-)3(A24-A92-2(A117-))18(A117-)A39-A3-A72-2A116-2A47-71A117-A3(117-116A2-116A1418-116A2-10(27A91-)3(A117-)3(A24-A92-2(A117-))18(A117-)A39-A3-A72-2A3(117-A))117-116A2-116A1418-116A2-10(27A91-)3(A117-)3(A24-A92-2(A117-))3(A117-)11(7A111-)4(A117-)A39-A3-A72-2A3(117-A)117-116A2-116A1418-116A2-10(27A91-)3(A117-)3(A24-A92-2(A117-))3(A117-)8(7A111-)7A70-3A38-2(7A111-)4(A117-)A39-A3-A72-2A3(117-A)117-116A2-116A1418-116A2-2(27A77-A4-A8-)27A77-6A8-7(27A91-)3(A117-)3(A24-A92-2(A117-))3(A117-)8(7A111-)7A70-A-A38-2(7A71-A39-)4(A77-A39-)A39-A3-A33-A38-2A3(77-A39-A)77-A39-116A2-116A1418-116A2-2(27A77-A4-A8-)27A77-6A8-7(27A91-)3(A117-)3(A24-A92-2(A117-))3(A117-)2(7A111-)6(5AC112-)5AC71-3A38-2(7A111-)2(4(A117-)A39-A3-A72-2A3(117-A)117-116A2-116A1418-116A2-2(27A77-A4-A8-)27A77-6A8-7(27A91-)3(A117-)3(A24-A92-2(A117-))3(A117-)11(7A111-))4(A117-)A39-A3-A72-2A3(117-A)117-116A2-116A1418-116A2-2(27A77-A4-A8-)27A77-6A8-7(27A91-)3(A117-)3(A24-A92-2(A117-))3(A117-)2(7A111-)7(5AC112-)2(7A111-)4(A117-)A39-A3-A72-2A3(117-A)117-116A2-116A1418-116A2-2(27A77-A4-A8-)27A77-6A8-7(27A91-)2(3(A117-)3(A24-A92-2(A117-))3(A117-)11(7A111-)4(A117-)A39-A3-A72-2A3(117-A)117-116A2-116A1418-116A2-10(27A91-))3(A117-)3(A24-A92-2(A117-))3(A117-)2(7A111-)7(5AC112-)2(7A111-)4(A117-)A39-A3-A72-2A3(117-A)117-116A2-116A1418-116A2-3(27A91-)27A7-3A81-6(27A91-)3(A117-)3(A24-A92-2(A117-))3(A117-)11(7A111-)4(A117-)A39-A3-A72-2A2(39-A77-A)117-A117-116A2-116A1418-116A2-3(27A8-A82-)27A7-A-A81-6(27A91-)3(A117-)3(A24-A92-2(A117-))3(A117-)11(7A111-)4(A117-)A39-A3-A72-2A2(39-A3-A73-A)117-A117-116A2-116A1418-116A2-3(27A91-)27A7-3A81-6(27A91-)3(A117-)3(A24-A92-2(A117-))3(A117-)2(7A111-)7(5AC112-)2(7A111-)4(A117-)A39-A3-A72-2A2(39-A3-A73-A)117-A117-2(116A2-116A1418-116A2-10(27A91-)3(A117-)3(A24-A92-2(A117-))3(A117-)11(7A111-)4(A117-)A116-2A117-A39-A3-A73-2(A117-))116A2-116A1418-116A2-10(27A91-)3(A117-)3(A24-A92-2(A117-))3(A117-)2(7A111-)7(5AC112-)2(7A111-)4(A117-)A116-2A117-A39-A3-A73-2(A117-)116A2-116A2(1418-116A2-10(27A91-)3(A117-)3(A24-A92-2(A117-))3(A117-)11(7A111-)4(A117-)A116-2A117-A39-A3-A73-2(A117-)6(2A3-)86A2-6(2A3-)86A)1418-116A2-9(27A91-)27A73-5A3(13-A99-A3-A)13-A24-A74-A3-A13-A99-5A13-A117-2(A24-A92-2(A117-))3(A117-)2(7A111-)7(5AC112-)2(7A111-)2(4(A117-)A116-2A117-A39-A3-A73-2(A117-)6(2A3-)86A2-6(2A3-)86A1418-116A2-3(27A77-A4-A8-)27A77-6A8-5(27A91-)27A73-5A3(13-A5-10A84-A3-A)13-A5-10A9-A74-A3-A13-A5-10A84-5A13-A5-10A102-A5-10A9-A92-2(A5-10A102-)A24-A92-5(A117-)11(7A111-))4(A117-)A116-2A117-A39-A3-A73-2(A117-)6(2A3-)86A2-6(2A3-)86A1314-A103-116A2-3(27A77-A4-A8-)27A77-6A8-5(27A91-)27A73-5A3(13-A5-10A84-A3-A)13-A5-10A9-A74-A3-A13-A5-10A84-5A13-A5-10A102-A5-10A9-A92-2(A5-10A102-)A24-A92-5(A117-)11(7A111-)4(A117-)2(A116-2A117-A39-A3-A73-2(A117-)6(2A3-)86A2-6(2A3-)86A1314-A103-116A2-3(27A77-A4-A8-)27A77-6A8-5(27A91-)27A73-5A3(13-A5-10A84-A3-A)13-A5-10A9-A74-A3-A13-A5-10A84-5A13-A5-10A102-A5-10A9-A92-2(A5-10A102-)A24-A92-20(A117-))A116-2A117-A39-A3-A73-2(A117-)6(2A3-)86A2-6(2A3-)86A1314-A103-116A2-3(27A77-A4-A8-)27A77-6A8-5(27A91-)27A73-5A3(13-A5-10A84-A3-A)13-A5-10A9-A74-A3-A13-A5-10A84-5A13-A5-10A102-A5-10A9-A92-A5-10A102-A5-10A89-5A8-A24-A79-4(A3-A8-A104-)5A8-3(A117-)A85-7A4(25-A85-3(A-)A)25-A85-7A25-7(A117-)A116-2A117-A39-A3-A73-2(A117-)6(2A3-)86A2-6(2A3-)86A1314-A103-116A2-3(27A77-A4-A8-)27A77-6A8-5(27A91-)27A73-5A3(13-A5-10A84-A3-A)13-A5-10A9-A74-A3-A13-A5-10A84-5A13-A5-10A102-A5-10A9-A92-A5-10A102-A5-10A89-5A8-A24-A79-4(A3-A8-A104-)5A8-3(A117-)A85-7A4(25-A85-3(AD)A)25-A85-7A25-3(A117-)4(A77-A2-A36-)A77-A2-A35-2A77-A2-A36-A39-A3-A33-A2-A36-2(A117-)6(2A3-)86A2-6(2A3-)86A1314-A103-116A2-3(27A13-A37-A2-A22-A4-A8-)27A13-A37-A2-A22-6A8-5(27A13-A37-A2-A36-)27A13-A37-A2-A18-5A3(13-A5-10A24-A37-A2-A18-A3-A)13-A5-10A9-A14-A37-A2-A18-A3-A13-A5-10A24-A37-A2-A18-5A13-A5-10A24-A37-A2-A36-A5-10A9-A14-2(A37-A2-A36-A5-10A24-)A37-A2-A23-5A8-A24-A14-4(A37-A2-A23-A3-A8-A39-)A37-A2-A23-5A8-3(A39-A37-A2-A36-)6(A39-A37-A2-A4-7A25-)4(A77-A2-A36-)3(A117-)A116-2A117-A39-A3-A33-A2-A36-2(A117-)6(2A3-)86A2-6(2A3-)86A1314-A103-116A2-3(27A13-A19-A43-A4-A8-)27A13-A19-A43-6A8-5(27A13-A19-A57-)27A13-A19-A39-5A3(13-A5-10A24-A19-A39-A3-A)13-A5-10A9-A14-A19-A39-A3-A13-A5-10A24-A19-A39-5A13-A5-10A24-A19-A57-A5-10A9-A14-2(A19-A57-A5-10A24-)A19-A44-5A8-A24-A14-4(A19-A44-A3-A8-A39-)A19-A44-5A8-3(A39-A19-A57-)6(A39-A19-A25-7A25-)4(A117-)3(A68-3A46-)A68-3A45-2A68-3A46-A39-A3-A24-3A6-A2-A36-2(A117-)6(2A3-)86A2-6(2A3-)86A1314-A103-116A2-3(27A13-A19-A43-A4-A8-)27A13-A19-A43-6A8-5(27A13-A19-A57-)27A13-A19-A39-5A3(13-A5-10A24-A19-A39-A3-A)13-A5-10A9-A14-A19-A39-A3-A13-A5-10A24-A19-A39-5A13-A5-10A24-A19-A57-A5-10A9-A14-2(A19-A57-A5-10A24-)A19-A44-5A8-A24-A14-4(A19-A44-A3-A8-A39-)A19-A44-5A8-3(A39-A19-A57-)3(A39-A19-A25-7A25-)A39-A19-A25-15A17-2(A39-A19-A25-7A25-)4(A117-)A68-3A46-2(A117-)A116-2A117-A39-A3-A24-3A6-2(A2-A36-A77-)A2-A36-6(2A3-)86A2-6(2A3-)86A1314-A103-116A2-3(27A13-A19-A8-3A32-A4-A8-)27A13-A19-A8-3A32-6A8-5(27A13-A19-A8-3A46-)27A13-A19-A8-3A28-5A3(13-A5-10A24-A19-A8-3A28-A3-A)13-A5-10A9-A14-A19-A8-3A28-A3-A13-A5-10A24-A19-A8-3A28-5A13-A5-10A24-A19-A8-3A46-A5-10A9-A14-2(A19-A8-3A46-A5-10A24-)A19-A8-3A33-5A8-A24-A14-4(A19-A8-3A33-A3-A8-A39-)A19-A8-3A33-5A8-3(A39-A19-A8-3A46-)3(A39-A19-A8-3A14-7A25-)A39-A19-A8-3A14-7A7-A17-2(A39-A19-A8-3A14-7A25-)5(A68-3A46-)355A117-A39-A3-A24-3A46-2(A117-)6(2A3-)86A2-6(2A3-)86A1314-A103-116A2-27A13-A19-A8-3A32-A4-A8-27A13-21A2(8-3A32-A4-A8-27A13-A19-A)8-3A32-6A8-27A13-21A2(8-3A46-27A13-A19-A)8-3A46-27A13-21A2(8-3A46-27A13-A19-A)8-3A28-5A13-A5-10A24-21A2(8-3A28-A3-A13-A5-10A24-A19-A)8-3A28-A3-A13-A5-10A9-A14-21A8-3A28-A3-A13-A5-10A24-A19-A8-3A28-5A13-A5-10A24-A19-A8-3A46-A5-10A9-A14-21A2(8-3A46-A5-10A24-A19-A)8-3A33-5A8-A24-A14-21A2(8-3A33-A3-A8-A39-A19-A)8-3A33-A3-A8-A39-21A8-3A33-A3-A8-A39-A19-A8-3A33-5A8-A39-A19-A8-3A46-A39-21A2(8-3A46-A39-A19-A)8-3A14-7A25-A39-21A8-3A14-12A20-A39-A19-A8-3A14-7A25-A39-A19-A8-3A14-7A7-A17-A39-21A8-3A14-7A25-A39-A19-A8-3A14-7A25-5(A68-3A46-)355A117-A39-A3-A24-3A46-2(A117-)6(2A3-)86A2-6(2A3-)86A1314-A103-116A2-3(27A13-A19-A8-3A32-A4-A8-)27A13-A19-A8-3A32-6A8-5(27A13-A19-A8-3A46-)27A13-A19-A8-3A28-5A3(13-A5-10A24-A19-A8-3A28-A3-A)13-A5-10A9-A14-A19-A8-3A28-A3-A13-A5-10A24-A19-A8-3A28-5A13-A5-10A24-A19-A8-3A14-3A29-A5-10A9-A14-2(A19-A8-3A14-3A29-A5-10A24-)A19-A8-3A14-3A16-5A8-A24-A14-2(A19-A8-3A33-A3-A8-A39-)2(A19-A8-3A12-3A18-A3-A8-A39-)A19-A8-3A12-3A18-5A8-A39-A19-A8-3A12-3A31-2(A39-A19-A8-3A46-)A39-A19-A8-3A14-7A25-A39-A19-A8-3A14-7A4-A20-A39-A19-A8-3A14-7A25-A39-A19-A8-3A14-7A7-A17-2(A39-A19-A8-3A14-7A25-)5(A68-3A46-)355A117-A39-A3-A24-3A46-2(A117-)116A2-116A1314-A103-116A2-3(27A13-A19-A8-3A32-A4-A8-)27A13-A19-A8-3A32-6A8-5(27A13-A19-A8-3A46-)27A13-A19-A8-3A28-5A3(13-A5-10A24-A19-A8-3A28-A3-A)13-A5-10A9-A14-A19-A8-3A28-A3-A13-A5-10A24-A19-A8-3A28-5A13-A5-10A24-A19-A8-3A14-3A29-A5-10A9-A14-2(A19-A8-3A14-3A29-A5-10A24-)A19-A8-3A14-3A16-5A8-A24-A14-2(A19-A8-3A33-A3-A8-A39-)2(A19-A8-3A12-3A18-A3-A8-A39-)A19-A8-3A12-3A18-5A8-A39-A19-A8-3A12-3A31-2(A39-A19-A8-3A46-)A39-A19-A8-3A14-7A25-A39-A19-A8-3A14-7A4-A20-A2-4A33-A19-A8-3A14-7A25-A2-4A33-A19-A8-3A14-7A7-A17-2(A2-4A33-A19-A8-3A14-7A25-)6(A68-3A46-)3(A117-)A39-A3-A24-3A46-2(A117-)116A2-116A1314-A103-116A2-4(27A13-A19-A8-3A32-6A8-)5(27A13-A19-A8-3A46-)27A13-A19-A8-3A28-5A3(13-A5-10A24-A19-A8-3A28-A3-A)13-A5-10A9-A14-A19-A8-3A28-A3-A13-A5-10A24-A19-A8-3A28-5A13-A5-10A24-A19-A8-3A14-3A29-A5-10A9-A14-2(A19-A8-3A14-3A29-A5-10A24-)A19-A8-3A14-3A16-5A8-A24-A14-2(A19-A8-3A33-A3-A8-A39-)2(A19-A8-3A12-3A18-A3-A8-A39-)A19-A8-3A12-3A18-5A8-A39-A19-A8-3A12-3A31-2(A39-A19-A8-3A46-)A39-A19-A8-3A14-7A25-A39-A19-A8-3A14-7A4-A20-A2-4A33-A19-A8-3A14-7A25-A2-4A33-A19-A8-3A14-7A7-A17-2(A2-4A33-A19-A8-3A14-7A25-)6(A68-3A46-)3(A117-)A39-A3-A24-3A46-2(A117-)116A2-116A1314-A103-116A33(2-41A19-56A)14(2-116A)2-11(A117-)15A143-20(21A33(97-A19-A)97-21A3047-)21A33(97-A19BA)97-21A3047-34(21A97-)21A3007-
