model
name = main
size = 66 17 32
scale = 0.05
origin = -y
shell = Outline 0.25
material type = toon, lighting = smooth, deform = 1 1
  colors = A:#C97373 B:#A6555F C:#A32858 D:#FFB879 E:#873555
material type = basic, lighting = smooth, roughness = 0, refractionRatio = 1, side = back
  colors = Outline:#000
voxels
991-2E22A5B33A2E1058-E13A10B20A6B13AE1058-5A9B18A12B8A12B1001-46B11-5B21A6B32A1001-46B11-64A79-E40-E12(24-B40-B)24-E40-E22-2BE40BE2B11-7A13B44A1001-46B11-20A26B18A397-D9(64-2D)9-46B9-2D46A14B4A67D330-4(D64-DC64-C)D64-DC9-46B9-CD8B56A16(DC)D2C16(DC)330-D2(64-2D)64-DC6(64-2C)9-46B9-2C64A67C330-D64-DC7(64-2C)64-CD9-46B9-DC28A9B2A3B2AB19A3CD29C2D29CD2C330-D64-2D64-DC5(64-2C)64-CD64-DC9-46B9-2C10A18B36A4CD18C7D3C2D3C7D18CD3C330-D64-DC8(64-2C)9-46B9-2C10B45A9B10CDCD2C5D3CD20CD3C5D2CDCD9C330-D64-2D64-DC3(64-2C)64-CD3(64-2D)9-46B9-2D37A18B9A7D5CD5C3D2C2D7C4D7C2D2C3D5CD5C6D330-D64-DC64-CD64-DC6(64-2C)9-46B9-2C28A9B27A12C5D3CD8CDC2D2C2DCD8CD3C5D11C2(330-D64-DC64-2C64-CD64-DC64-CD4(64-2D)9-46B9-2D64A8D12C4D20C4D12C7D)330-D64-DC64-CD64-DC6(64-2C)9-46B9-2C64A12C5D3CD8CDC2D2C2DCD8CD3C5D11C330-D64-2D64-DC3(64-2C)64-CD3(64-2D)9-46B9-2D2B6A13B43A7D5CD5C3D2C2D7C4D7C2D2C3D5CD5C6D330-D64-DC8(64-2C)9-46B9-2C21A24B19A10CDCD2C5D3CD20CD3C5D2CDCD9C330-D64-2D64-DC5(64-2C)64-CD64-DC9-46B9-2C45A13B2A2(BA)4CD18C7D3C2D3C7D18CD3C330-D64-DC7(64-2C)64-CD9-46B9-DC64A3CD29C2D29CD2C330-D2(64-2D)64-DC6(64-2C)9-46B9-2C28AB5A9B21A67C330-4(D64-DC64-C)D64-DC9-46B9-CD8B34A2B20A16(DC)D2C16(DC)330-D9(64-2D)9-46B9-2D8A14B42A67D934-46B11-22A7B35A79-E40-E12(24-B40-B)24-E40-E22-2BE40BE2B11-47A17B1001-46B11-30A17B17A1001-46B11-12B52A1058-12A11B28A3B3AB6A1058-E62AE1058-2E60A2E67-
