model
name = main
size = 21 32 21
scale = 0.05
origin = -y
shell = Outline 0.25
material type = toon, lighting = smooth, deform = 1 1
  colors = A:#808080 B:#0C1C0C C:#340808 D:#4C2808
material type = basic, lighting = smooth, roughness = 0, refractionRatio = 1, side = back
  colors = Outline:#000
voxels
407-5B17-3B19-B37-3B2-4B13-2B3-3B495-3B2-4B13-2B3-3B34-6B15-2B3AB14-3CBA2B2C12-3C4B2C10-2B3A2B4AB10-2B2A3B3AB11-4B-4B15-3B19-B435-11B10-2B2ABCB3AB11-2B4C3B9-4B6A4B8-3B6A4B9-B9A2B10-C8AC9-2B10AB8-B11AB9-2B3AC3A2B12-2B3A2B15-2BA2B17-3B394-C17-3BAC4BC2B2(10-B9AB)7-3B11A2B6-B13AB6-2B12AB7-2B10A2(B8-B11A)B9-B9AB9-3B7A2B10-3B5A3B13-B3AB17-3B353-4B15-4CB3C12-B8ACB10-B9AB8-2C11AC6-B14A2B4-B15AB5-B14AB5-B13AB5-2B13A2B5-B13A2B5-2C11ACB6-B12AC8-B11AC9-4B4A4B11-B-4B-B348-9B12-B7AB8-4B9A4B4-2BC11A3B5-C13AB5-3(B15AB4-)C14AB4-B16A2B2-2B16AB3-B15AB5-B13AB6-B13AB7-2B10AB10-3B4A3B13-6B327-11B10-B9AB6-4B11AC3B2-B17AB3-2(B15AB4-)B15AB3-C16AC3-C16A2C-B19AB-B18AB2-B15A2B4-B13AB6-B13AB7-B11AB9-2B8AB12-8B326-11B8-2C11AC5-2B14AC2B2-B17AB3-B15AB3-2(B17AB2-)C17AC2-C17AC-B19AB-B18AB2-B16AB4-B14AB6-B12AB7-B11AB9-B9AB11-3B4A2B15-4B306-12B8-C12A2C4-2B15A2B2-B17AB3-B15AB2-2B17A3B18AB2-B17AC3-C16AC-2B18AB-B18AB2-B16AB3-B15AB4-2B14AB5-B13AB7-2B10AB10-2B6A2B13-6B15-3(4D17-)4D10(18-3D)13-5B3A5B8-C11AC6-2B13A3B3-B15AB4-C15AC2-2B17A3B19AB-2(B17AB2-)B18AB-B17AB2-C17AB2-B16AC4-B15AC5-B14AB6-B11A2B8-3B6A2B13-6B15-4(D2-D17-)2(2D-D17-)2D7(-D18-D)-D13-5BABA5B7-B12AB6-B14A2B4-C15AB3-C16AC2-B18A3B19AB-B18AB-B17AB2-B17AB3-C16AB2-C16AC3-C17AB3-C16AB4-B14AB6-B11A2B8-2B7A2B12-7B16-3(D-D18-)3(3D18-)3D7(19-2D)13-6B2A5B8-C11AC5-3B13A2B3-B16AB4-C15AC2-2B17A3B19AB-B17AB3-B16AB-2B17AB2-B17AB3-C16AB2-B17AB3-B15AB5-B14AB6-2B10A2B9-2B6A2B13-6B17-3(2D19-)2(D20-)D183-12B7-2C12AC4-2B15A2B2-B17AB3-B15AB3-B17A2B-B2(17AB2-C)16AC2-B18A2B-B18AB2-B16AB3-B15AB5-B14AB6-B11A2B8-B9AB11-2B5A3B13-5B307-11B9-C11A2C4-3B14A2B2-B17AB3-B15AB4-B16AB3-B16AB2(2-C17AC)-B19AB-B18AB2-B16AB4-B14AB5-B13AB7-B11AB9-B9A2B10-4BA4B16-B309-11B10-C9ABC6-3B12A3B3-B15AB5-B14A2(B4-B15A)B4-C16AC3-C16AC-2B18AB-B17AB3-B15A2B4-B13AB6-B13AB7-B11AB9-2B7A2B12-7B328-9B12-C7AB9-3B9A4B5-2B11A3B5-C13AB5-2(B15AB4-)B15AC5-B14AC3-2B16AB3-B15A2B4-C13AB6-B13AB7-B12AB8-B9A2B10-4B2A3B16-2B333-3B16-2CAB3C11-3B7A2B-B8-C9AB9-C11AC6-2B13A2B4-B15AB5-B13AB7-B12AB5-2B13A3B4-B13AB7-C11AC8-B12AB8-B7AB2AB10-3B4A3B14-4B373-2C2-2C12-3B2(2A2B)10-B4AC4AB10-CB8AB8-2B11A3B5-B13AB7-B11A2B8-C9A2B2(8-B11AB)9-C9AB10-3B5A4B10-3B3AB-2B14-4B412-11B11-B2AB-B3AB12-2B2CA3B10-4B5A5B7-4B5A4B9-C2AB6AB10-C2ACB2ACAC10-B5AB4A2B9-B4AC4AB11-2BAC2A4B13-B3AB17-4B434-4B-4B13-3B2-3B16-2C17-2B2AB16-B3AB14-2C-4B2C12-2C2-2B-2C11-B2A2B-2B2AB11-2BAB-5B13-B-2C18-3B522-4B17-4B56-4B2-3B14-B159-
