model
name = main
size = 16 32 3
scale = 0.05
origin = -y
material type = toon, lighting = smooth, deform = 1 1 
  colors = A:#4A3052 B:#1F102A C:#7B5480
voxels
16B2(6(7AB)2(C6AB)7CB7C17B3A4(B7A)BC6ABC3A3CB7CB4C17B4(7AB)2(C6AB)7CB7C16B4A4(B7A)BC6ABC2A4CB7CB3C16B4(7AB)2(C6AB)7CB7C17B3A4(B7A)BC6ABC3A3CB7CB4C32B)6(7AB)2(C6AB)7CB7C17B3A4(B7A)BC6ABC3A3CB7CB4C17B4(7AB)2(C6AB)7CB7C16B4A4(B7A)BC6ABC2A4CB7CB3C16B4(7AB)2(C6AB)7CB7C17B3A4(B7A)BC6ABC3A3CB7CB4C16B
