model
name = main
size = 6 32 6
scale = 0.05
origin = -y
material type = toon, lighting = smooth, deform = 1 1 
  colors = A:#A6555F B:#C97373 C:#7B5480 D:#A6859F
voxels
18-7CD2CD7C120-7CD2CD7C19-B2AB2-AB2A2-2ABA-C2(BA)CDB2ABDCB2ABC-2(BA2B2-)2ABA2-2(BA)2-A2BA2-B2AB2(2-2(BA))2-B3A2(2-2(BA))2-BA2B2-2A2B2-B2AB2(2-2(BA))2-AB2A2-2(BA)2-2B2A2-2A2B-CBA2BCDBA2BDC2ABAC-2ABA2-B3A2-B2AB2-4A2-B3A2-B2AB-C2(B2AB2C)B2ABC-B2AB2-3AB2-B3A3(2-3AB)2-4A2(2-3AB)2-4A2-3AB4(2-4A)4(2-3AB)2-B2AB-CB2AB2(2CB3A)C-2(3AB2-)A3B2-4A2-3AB2-4A-C2(4A2C)4AC-2(4A2-)3AB2-4A4(2-B3A)2(2-4A)4(2-B2AB)2(2-B3A)4(2-4A)-C4A2(2C3AB)C-4A2-3AB2-A2BA2-B2AB2(2-2(AB))-C2(AB)CDABACDC2BA2C-A2BA2-4B2-B2AB2-2BAB2(2-2(AB))2-3AB2-2(AB)2-2BAB2(2-BA2B)2(2-A2BA)2-AB2A2(2-2(AB))2-3AB2-2(AB)2-2BAB2-2(BA)-C2(BA)CD2ABADCBA2BC-2(BA)2-2ABA2-BA2B19-7CD2CD7C120-7CD2CD7C18-
