model
name = main
size = 14 30 7
scale = 0.05
origin = -y
material type = toon, lighting = smooth, deform = 1 1 
  colors = A:#5BA675 B:#A6555F C:#873555 D:#4A3052 E:#FFF F:#D9BDC8 G:#EE8FCB
voxels
--AAA----AAA-- -------------- -------------- -------------- -------------- -------------- -------------- -------------- -------------- -------------- -------------- -------------- -------------- -------------- -------------- -------------- -------------- -------------- -------------- -------------- -------------- -------------- -------------- -------------- -------------- -------------- -------------- -------------- -------------- -------------- 
--AAA----AAA-- --AAA----AAA-- -------------- -------------- -------------- -------------- -------------- -------------- -------------- -------------- -------------- -------------- -------------- -------------- -------------- -------------- -------------- -------------- ----AAAAAA---- ----AAAAAA---- ----AAAAAA---- ----AAAAAA---- ----AAAAAA---- -------------- -------------- -------------- -------------- -------------- -------------- -------------- 
--AAA----AAA-- --AAA----AAA-- --CCC----CCC-- -------------- -------------- -------------- -------------- -------------- -------------- -------------- -------------- -------------- ------BB------ ------BB------ ------AA------ ------AA------ ------AA------ ------AA------ ----AAAAAA---- ----AAAAAA---- ----AAAAAA---- ----AAAAAA---- ----AAAAAA---- -------------- -----AAAA----- ------EE------ -----AAAA----- -----DAAD----- -------AD----- -------AA----- 
--AAA----AAA-- --AAA----AAA-- --CAC----CAC-- --CCC----CCC-- --CCC----CCC-- ---C------C--- --BBB----BBB-- --BBB----BBB-- --BBB----BBB-- --BBB----BBB-- --BBB-BB-BBB-- ---B-BBBB-B--- ---BBBAABBB--- ---BBBAABBB--- -----AAAA----- -----AAAA----- -----AAAA----- -----AAAA----- ----AAAAAA---- ----AAAAAA---- ----AAAAAA---- --A-AAAAAA-A-- --AAAAAAAAAA-- ---A------A--- -----AAAA----- -----FAAF----- -----AAAA----- -----AAAA----- ------GGA----- -------AA----- 
--AAA----AAA-- --AAA----AAA-- --CCC----CCC-- --CCC----CCC-- --CCC----CCC-- ---C------C--- --BBB----BBB-- --BBB----BBB-- --BBB----BBB-- --BBB----BBB-- --BBB-BB-BBB-- ---B-BBBB-B--- A--BBBBBBBB--A A--BBBAABBB--A A----AAAA----A A----AAAA----A AA---AAAA---AA -A---AAAA---A- -AA-AAAAAA-AA- --A-AAAAAA-A-- --A-AAAAAA-A-- -AA-AAAAAA-AA- --AAAAAAAAAA-- ---A------A--- -----AAAA----- -----AAAA----- -----AAAA----- -----AAAA----- -----AAAA----- -----AAAA----- 
---A------A--- -------------- -------------- -------------- -------------- -------------- -------------- -------------- -------------- -------------- -------------- -------------- -------------- ------BB------ ------AA------ ------AA------ ------AA------ ------AA------ ----AAAAAA---- ----AAAAAA---- ----AAAAAA---- --A-AAAAAA-A-- --AAAAAAAAAA-- ---A--AA--A--- ------AA------ ------AA------ -----AAAA----- -----AAAA----- -----AAAA----- -----AAAA----- 
-------------- -------------- -------------- -------------- -------------- -------------- -------------- -------------- -------------- -------------- -------------- -------------- -------------- -------------- ------AA------ ------AA------ ------AA------ ------AA------ ------AA------ ------AA------ ------AA------ ------AA------ ------AA------ -------------- -------------- -------------- -----AAAA----- -----AAAA----- -----AAAA----- -----AAAA----- 
