model
name = main
size = 10 24 10
scale = 0.05
origin = -y
shell = Outline 0.25
material type = toon, lighting = smooth, deform = 1 1
  colors = A:#A6555F B:#C97373 C:#873555
material type = basic, lighting = smooth, roughness = 0, refractionRatio = 1, side = back
  colors = Outline:#000
voxels
---------- ---------- ---------- ---------- ---------- ---------- ---------- AAAAAAAAAA ABBABBABBA ---------- ---------- ---------- ---------- ---------- ---------- ---------- ---------- ---------- ---------- ---------- ---------- ---------- ---------- ---------- 
-C------C- -A------A- -A------A- -A------A- -A------A- -A------A- -C------C- AAAAAAAAAA ABBABBABBA ---------- ---------- C--------C ---------- ---------- ---------- ---------- ---------- ---------- ---------- ---------- ---------- ---------- ---------- ---------- 
---------- ---------- ---------- ---------- ---------- ---------- ---------- AAAAAAAAAA ABBABBABBA ---------- ---------- A--------A ---------- ---------- ---------- ---------- ---------- ---------- ---------- ---------- ---------- ---------- ---------- ---------- 
---------- ---------- ---------- ---------- ---------- ---------- ---------- AAAAAAAAAA ABBABBABBA C--------C A--------A A--------A ---------- ---------- ---------- ---------- ---------- ---------- ---------- ---------- ---------- ---------- ---------- ---------- 
---------- ---------- ---------- ---------- ---------- ---------- ---------- AAAAAAAAAA ABBABBABBA ---------- ---------- A--------A ---------- ---------- ---------- ---------- ---------- ---------- ---------- ---------- ---------- ---------- ---------- ---------- 
---------- ---------- ---------- ---------- ---------- ---------- ---------- AAAAAAAAAA ABBABBABBA ---------- ---------- A--------A ---------- ---------- ---------- ---------- ---------- ---------- ---------- ---------- ---------- ---------- ---------- ---------- 
---------- ---------- ---------- ---------- ---------- ---------- ---------- AAAAAAAAAA ABBABBABBA ---------- ---------- A--------A ---------- ---------- ---------- ---------- ---------- ---------- ---------- ---------- ---------- ---------- ---------- ---------- 
---------- ---------- ---------- ---------- ---------- ---------- ---------- AAAAAAAAAA ABBABBABBA ---------- ---------- A--------A ---------- ---------- ---------- ---------- ---------- ---------- ---------- ---------- ---------- ---------- ---------- ---------- 
-C------C- -A------A- -A------A- -A------A- -A------A- -A------A- -C------C- AAAAAAAAAA AAAAAAAAAA ---------- ---------- A--------A ---------- ---------- ---------- ---------- ---------- ---------- ---------- ---------- ---------- ---------- ---------- ---------- 
---------- ---------- ---------- ---------- ---------- ---------- ---------- AAAAAAAAAA ABBABBABBA AAAAAAAAAA ABBABBABBA ABBABBABBA ABBABBABBA ABBABBABBA ABBABBABBA ABBABBABBA ABBABBABBA ABBABBABBA ABBABBABBA AABABBABAA -AAABBAAA- --AABBAA-- ---AAAA--- ----AA---- 
