model
name = main
size = 7 16 3
scale = 0.05
origin = -y
material type = toon, lighting = smooth, deform = 1 1 
  colors = A:#D9BDC8 B:#A6859F C:#A6555F D:#C97373
voxels
---C--- ------- ------- ------- ------- ------- ------- ------- ------- ------- ------- --AAA-- --AAA-- --AAA-- ------- ------- 
--CDC-- ---C--- ---D--- ---C--- ---D--- ---C--- ---D--- ---C--- ---D--- -B-C-B- BB-D-BB BAACAAB BBADABB BAACAAB BB-D-BB -B---B- 
---C--- ------- ------- ------- ------- ------- ------- ------- ------- ------- ------- --AAA-- --AAA-- --AAA-- ------- ------- 
