model
name = main
size = 10 19 10
scale = 0.05
origin = -y
material type = toon, lighting = smooth, deform = 1 1 
  colors = A:#A6555F B:#C97373 C:#873555
voxels
---------- ---------- ---------- ---------- ---------- ---------- ---------- ---------- ---------- ---------- ---------- ---------- ---------- ---------- ---------- ---------- ---------- AAAAAAAAAA BBBBBBBBBB 
-C------C- -A------A- -A------A- -A------A- -A------A- -A------A- -A------A- -A------A- -A------A- -A------A- -A------A- -A------A- -A------A- -A------A- -A------A- -A------A- -C------C- AAAAAAAAAA BBBBBBBBBB 
---------- ---------- ---------- ---------- ---------- ---------- ---------- ---------- ---------- ---------- ---------- ---------- ---------- ---------- ---------- ---------- ---------- AAAAAAAAAA AAAAAAAAAA 
---------- ---------- ---------- ---------- ---------- ---------- ---------- ---------- ---------- ---------- ---------- ---------- ---------- ---------- ---------- ---------- ---------- AAAAAAAAAA BBBBBBBBBB 
---------- ---------- ---------- ---------- ---------- ---------- ---------- ---------- ---------- ---------- ---------- ---------- ---------- ---------- ---------- ---------- ---------- AAAAAAAAAA BBBBBBBBBB 
---------- ---------- ---------- ---------- ---------- ---------- ---------- ---------- ---------- ---------- ---------- ---------- ---------- ---------- ---------- ---------- ---------- AAAAAAAAAA BBBBBBBBBB 
---------- ---------- ---------- ---------- ---------- ---------- ---------- ---------- ---------- ---------- ---------- ---------- ---------- ---------- ---------- ---------- ---------- AAAAAAAAAA BBBBBBBBBB 
---------- ---------- ---------- ---------- ---------- ---------- ---------- ---------- ---------- ---------- ---------- ---------- ---------- ---------- ---------- ---------- ---------- AAAAAAAAAA AAAAAAAAAA 
-C------C- -A------A- -A------A- -A------A- -A------A- -A------A- -A------A- -A------A- -A------A- -A------A- -A------A- -A------A- -A------A- -A------A- -A------A- -A------A- -C------C- AAAAAAAAAA BBBBBBBBBB 
---------- ---------- ---------- ---------- ---------- ---------- ---------- ---------- ---------- ---------- ---------- ---------- ---------- ---------- ---------- ---------- ---------- AAAAAAAAAA BBBBBBBBBB 
