model
name = main
size = 24 23 19
scale = 0.05
origin = -y
shell = Outline 0.25
material type = toon, lighting = smooth, deform = 1 1
  colors = A:#808080 B:#340808 C:#3C5004
material type = basic, lighting = smooth, roughness = 0, refractionRatio = 1, side = back
  colors = Outline:#000
voxels
------------------------ ------------------------ ------------------------ ------------------------ ------------------------ -------BBBB------------- -------BBBBB------------ ------BBBBBBB----------- -----BBBBBBBB----------- -----BBBBBBBB----------- ------BBBBBBB----------- ------BBBBBBB----------- -------BBBBB------------ --------BBB------------- ------------------------ ------------------------ ------------------------ ------------------------ ------------------------ ------------------------ ------------------------ ------------------------ ------------------------ 
------------------------ ------------------------ ------------------------ --------B--------------- ------BBBBBBB----------- ----BBBAAAABBB---------- ----BBBAAAAABB---------- ----BBAAAAAAABB--------- ---BBAAAAAAAABB--------- ---BBAAAAAAAABB--------- ----BBAAAAAAABB--------- ----BBAAAAAAABB--------- ----BBBAAAAABB---------- -----BBBAAABBB---------- -------BBBBBB----------- ---------B-------------- ------------------------ ------------------------ ------------------------ ------------------------ ------------------------ ------------------------ ------------------------ 
------------------------ ------------------------ -------BBBB------------- -----BBBABBBB----------- ----BBAAAAAAAB---------- ---BAAAAAAAAAAB--------- --BBAAAAAAAAAABB-------- --BBAAAAAAAAAAAB-------- --BAAAAAAAAAAAAB-------- --BAAAAAAAAAAAAB-------- --BBAAAAAAAAAAAB-------- --BBAAAAAAAAAAAB-------- ---BAAAAAAAAAABB-------- ----BAAAAAAAAAB--------- -----BBAAAAAAB---------- ------BBBABBB----------- --------BBB------------- ------------------------ ------------------------ ------------------------ ------------------------ ------------------------ ------------------------ 
------------------------ ------------------------ -----BBBBBBBB----------- ----BAAAAAAAAB---------- ---BAAAAAAAAAAB--------- --BAAAAAAAAAAAAB-------- --BAAAAAAAAAAAAB-------- -BAAAAAAAAAAAAAAB------- -BAAAAAAAAAAAAAAB------- -BAAAAAAAAAAAAAAB------- -BAAAAAAAAAAAAAAB------- --BAAAAAAAAAAAAAB------- --BAAAAAAAAAAAAB-------- ---BAAAAAAAAAAAB-------- ----BAAAAAAAAAB--------- -----BAAAAAAABB--------- ------BBBBBBB----------- -------------CCCC------- ------------CCCCC------- ------------------------ ------------------------ ------------------------ ------------------------ 
------------------------ ------BBBBBB------------ ----BBAAAAAABB---------- ---BAAAAAAAAAAB--------- --BAAAAAAAAAAAAB-------- -BAAAAAAAAAAAAAAB------- -BAAAAAAAAAAAAAAB------- -BAAAAAAAAAAAAAAB------- -BAAAAAAAAAAAAAAAB------ -BAAAAAAAAAAAAAAAB------ -BAAAAAAAAAAAAAAAB------ -BAAAAAAAAAAAAAAB------- -BAAAAAAAAAAAAAAB------- --BAAAAAAAAAAAAAB------- ---BAAAAAAAAAAAB-------- ----BAAAAAAAAAB--------- -----BBAAAAAAB---CCC---- -------BBBBBBACCCCCC---- ----------CCAAACCC------ -----------CCCC--------- ------------------------ ------------------------ ------------------------ 
------------------------ -----BBBBBBBB----------- ---BBAAAAAAAABB--------- --BAAAAAAAAAAAAB-------- --BAAAAAAAAAAAAAB------- -BAAAAAAAAAAAAAAB------- -BAAAAAAAAAAAAAAAB------ BAAAAAAAAAAAAAAAAB------ BAAAAAAAAAAAAAAAAB------ BAAAAAAAAAAAAAAAAB------ BAAAAAAAAAAAAAAAAB------ -BAAAAAAAAAAAAAAAB------ -BAAAAAAAAAAAAAAAB------ -BAAAAAAAAAAAAAAB------- --BAAAAAAAAAAAAAB------- ---BAAAAAAAAAAAB---CC--- ----BAAAAAAAAAB---CAC--- -----BBBBAAAAB-CCCACC--- ---------BCAAACAACC----- -----------CCCCCC------- ------------------------ ------------------------ ------------------------ 
--------BB-------------- ----BBBBAABBBB---------- ---BAAAAAAAAAAB--------- --BAAAAAAAAAAAAB-------- -BAAAAAAAAAAAAAAB------- -BAAAAAAAAAAAAAAAB------ BAAAAAAAAAAAAAAAAB------ BAAAAAAAAAAAAAAAAB------ BAAAAAAAAAAAAAAAAB------ BAAAAAAAAAAAAAAAAB------ BAAAAAAAAAAAAAAAAB------ BAAAAAAAAAAAAAAAAB------ BAAAAAAAAAAAAAAAAB------ -BAAAAAAAAAAAAAAAB------ --BAAAAAAAAAAAAAB----CC- ---BAAAAAAAAAAAB----CCC- ----BAAAAAAAAABB--CCAC-- -----BBBAAAAAB--CCAAC--- --------BBAAAACCAACC---- ----------CCCCCCCC------ ------------------------ ------------------------ ------------------------ 
-------BBBB------------- ----BBBAAAABBB---------- --BBAAAAAAAAAABB-------- --BAAAAAAAAAAAAAB------- -BAAAAAAAAAAAAAAB------- BAAAAAAAAAAAAAAAAB------ BAAAAAAAAAAAAAAAAB------ BAAAAAAAAAAAAAAAAB------ BAAAAAAAAAAAAAAAAB------ BAAAAAAAAAAAAAAAAB------ BAAAAAAAAAAAAAAAAB------ BAAAAAAAAAAAAAAAAB------ BAAAAAAAAAAAAAAAAB------ -BAAAAAAAAAAAAAAAB----CC --BAAAAAAAAAAAAAB----CAC --BAAAAAAAAAAAAAB---CAC- ---BBAAAAAAAAABB---CACC- -----BBAAAAAAB--CCCAC--- -------BBBAAAACCAACC---- ----------CCCCCCCC------ ------------------------ ------------------------ ------------------------ 
------BBBBBB------------ ----BBAAAAAABBB--------- --BBAAAAAAAAAAAB-------- -BAAAAAAAAAAAAAAB------- -BAAAAAAAAAAAAAAB------- BAAAAAAAAAAAAAAAAB------ BAAAAAAAAAAAAAAAAB------ BAAAAAAAAAAAAAAAAB------ BAAAAAAAAAAAAAAAAAB----- BAAAAAAAAAAAAAAAAAB----- BAAAAAAAAAAAAAAAAAB----- BAAAAAAAAAAAAAAAAB------ BAAAAAAAAAAAAAAAAB----CC -BAAAAAAAAAAAAAAAB----CC -BAAAAAAAAAAAAAAB----CAC --BAAAAAAAAAAAAAB---CAC- ---BAAAAAAAAAAAB---CAAC- ----BBAAAAAAAAB--CCAAC-- ------BBBAAAAAACCACCC--- ---------CAAAACCCC------ ----------CCCC---------- ------------CC---------- ------------------------ 
-------BBBBB------------ ----BBBAAAAABBB--------- --BBAAAAAAAAAAAB-------- -BAAAAAAAAAAAAAAB------- -BAAAAAAAAAAAAAAB------- BAAAAAAAAAAAAAAAAB------ BAAAAAAAAAAAAAAAAB------ BAAAAAAAAAAAAAAAAB------ BAAAAAAAAAAAAAAAAB------ BAAAAAAAAAAAAAAAAAB----- BAAAAAAAAAAAAAAAAB------ BAAAAAAAAAAAAAAAAB------ BAAAAAAAAAAAAAAAAB-----C -BAAAAAAAAAAAAAAAB----CC -BAAAAAAAAAAAAAAB----CAC --BAAAAAAAAAAAAAB---CAC- ---BBAAAAAAAAABB---CAAC- -----BBAAAAAAB---CCAAC-- -------BAAAAAACCCACCC--- --------CAAAAAACCC------ ---------CCAAAC--------- -----------CCCC--------- ------------------------ 
--------BBB------------- ----BBBBAAABBB---------- ---BAAAAAAAAAABB-------- --BAAAAAAAAAAAAAB------- -BAAAAAAAAAAAAAAB------- BAAAAAAAAAAAAAAAAB------ BAAAAAAAAAAAAAAAAB------ BAAAAAAAAAAAAAAAAB------ BAAAAAAAAAAAAAAAAB------ BAAAAAAAAAAAAAAAAB------ BAAAAAAAAAAAAAAAAB------ BAAAAAAAAAAAAAAAAB------ BAAAAAAAAAAAAAAAAB------ -BAAAAAAAAAAAAAAAB-----C --BAAAAAAAAAAAAAB----CC- --BAAAAAAAAAAAAAB---CAC- ---BBAAAAAAAAABB---CAC-- -----BBAAAAAAB--CCCAC--- -------CAAAAAACCAACC---- --------CAAAAACCCC------ ---------CAAAC---------- ----------CCCACC-------- -------------CCC-------- 
---------BB------------- -----BBBBAABBB---------- ---BBAAAAAAAAABB-------- --BAAAAAAAAAAAAB-------- -BAAAAAAAAAAAAAAB------- -BAAAAAAAAAAAAAAAB------ -BAAAAAAAAAAAAAAAB------ BAAAAAAAAAAAAAAAAB------ BAAAAAAAAAAAAAAAAB------ BAAAAAAAAAAAAAAAAB------ BAAAAAAAAAAAAAAAAB------ -BAAAAAAAAAAAAAAAB------ -BAAAAAAAAAAAAAAAB------ -BAAAAAAAAAAAAAAAB------ --BAAAAAAAAAAAAAB----CC- ---BAAAAAAAAAAAB---CCC-- ----BAAAAAAAAAB---CAAC-- -----BBAAAAAAB--CCACC--- -------CABAAAACCACC----- --------CACAACCCC------- ---------CAAC----------- ----------CCACCCC------- ------------CCCC-------- 
------------------------ -----BBBBBBBBB---------- ----BAAAAAAAAAB--------- --BBAAAAAAAAAAAB-------- --BAAAAAAAAAAAAAB------- -BAAAAAAAAAAAAAAB------- -BAAAAAAAAAAAAAAAB------ -BAAAAAAAAAAAAAAAB------ BAAAAAAAAAAAAAAAAB------ BAAAAAAAAAAAAAAAAB------ -BAAAAAAAAAAAAAAAB------ -BAAAAAAAAAAAAAAAB------ -BAAAAAAAAAAAAAAAB------ --BAAAAAAAAAAAAAB------- --BAAAAAAAAAAAAB-------- ---BAAAAAAAAAAAB----CC-- ----BBAAAAAAABB--CCCC--- ------BBABABB--CCAAC---- -------CC-CAACCACCC----- -------CAC-CCCCC-------- --------CCCC------------ ----------CCCCCCC------- ------------CCCCC------- 
------------------------ ------BBBBBBB----------- -----BAAAAAAAB---------- ---BBAAAAAAAAABB-------- ---BAAAAAAAAAAAB-------- --BAAAAAAAAAAAAAB------- -BAAAAAAAAAAAAAAB------- -BAAAAAAAAAAAAAAAB------ -BAAAAAAAAAAAAAAAB------ -BAAAAAAAAAAAAAAAB------ -BAAAAAAAAAAAAAAAB------ -BAAAAAAAAAAAAAAB------- --BAAAAAAAAAAAAAB------- --BAAAAAAAAAAAAB-------- ---BAAAAAAAAAAAB-------- ----BBAAAAAAAAB--------- ------BBAAABBB----CC---- --------BBB--CCCCCC----- --------C--CCACCCC------ -------CAC--CC---------- --------CCCC------------ ----------CCCCCCC------- ------------CCCCC------- 
------------------------ ---------B-------------- ------BBBABBB----------- ----BBAAAAAAABB--------- ---BAAAAAAAAAAAB-------- ---BAAAAAAAAAAAB-------- --BAAAAAAAAAAAAAB------- --BAAAAAAAAAAAAAB------- --BAAAAAAAAAAAAAB------- --BAAAAAAAAAAAAAB------- --BAAAAAAAAAAAAAB------- --BAAAAAAAAAAAAAB------- --BAAAAAAAAAAAAB-------- ---BAAAAAAAAAAAB-------- ----BAAAAAAAAAB--------- -----BBAAAAABB---------- -------BBBBB------------ --------------CCCC------ ------------CC---------- --------CC-------------- ---------CCC------------ ----------CCCCCCCC------ ------------CCCCCC------ 
------------------------ ------------------------ -------BBBBB------------ -----BBAAAAABB---------- ----BBAAAAAAABB--------- ----BAAAAAAAAABB-------- ---BAAAAAAAAAAAB-------- ---BAAAAAAAAAAAB-------- --BAAAAAAAAAAAAAB------- --BAAAAAAAAAAAAAB------- ---BAAAAAAAAAAAB-------- ---BAAAAAAAAAAAB-------- ---BBAAAAAAAAABB-------- ----BBAAAAAAABB--------- -----BBAAAAABB---------- -------BBBBB------------ ------------------------ ------------------------ ------------------------ ---------C-------------- ---------CCC------------ ----------CCCCCCCC------ ------------CCCCCC------ 
------------------------ ------------------------ ------------------------ -------BBBBB------------ ------BBBBBBB----------- -----BAAAAAABB---------- ----BBAAAAAAABB--------- ----BBAAAAAAAAB--------- ---BBAAAAAAAAABB-------- ---BBAAAAAAAAABB-------- ----BAAAAAAAAAB--------- ----BBAAAAAAABB--------- -----BAAAAAAAB---------- ------BBBABBB----------- -------BBBBB------------ ------------------------ ------------------------ ------------------------ ------------------------ ------------------------ ----------CCC----C------ -----------CCCCCCC------ -------------CCCCC------ 
------------------------ ------------------------ ------------------------ ------------------------ ------------------------ ------BBBBBB------------ ------BBBBBBB----------- ------BBBBBBBB---------- -----BBBBAABBB---------- -----BBBBAABBB---------- -----BBBBBBBBB---------- ------BBBBBBB----------- ------BBBBBBB----------- ---------B-------------- ------------------------ ------------------------ ------------------------ ------------------------ ------------------------ ------------------------ -----------CCCCCCCC----- -------------CCCCCC----- ------------------------ 
------------------------ ------------------------ ------------------------ ------------------------ ------------------------ ------------------------ ------------------------ ------------------------ ---------BB------------- ---------BB------------- ------------------------ ------------------------ ------------------------ ------------------------ ------------------------ ------------------------ ------------------------ ------------------------ ------------------------ ------------------------ -------------CCCCCC----- ------------------------ ------------------------ 
