model
name = main
size = 48 45 38
scale = 0.05
origin = -y
material type = toon, lighting = smooth, deform = 1 1 
  colors = A:#808080 B:#340808 C:#3C5004
voxels
688-3B45-4B43-7B40-9B40-8B40-7B42-4B45-2B1628-6B41-8B39-11B37-12B35-4B3A6B34-5B4A6B32-5B7A4B32-4B9A3B32-5B8A4B32-4B7A4B34-4B4A6B34-5B2A6B36-12B37-10B39-8B41-6B1338-4B42-9B36-4B6A4B33-4B8A4B32-3B11A2B31-4B12A2B30-3B13A2B30-2B15AB29-2(2B16A2B28-)2B17AB29-2B15A2B29-3B14A2B29-3B13A2B31-3B12A2B31-4B10A2B33-4B8A3B34-4B6A3B37-10B40-4B1149-B44-8B38-4B4A5B33-4B9A3B31-2B14A2B30-B16A2B28-2B16A2B28-B18AB28-B18A2B26-2B18A2B26-3(B20A2B25-)2B19A2B26-B19AB27-B18A2B27-2B17A2B27-2B16A2B29-2B15A2B30-2B13A2B32-3B10A2B35-3B4A5B38-8B42-2B1004-6B40-4BA6B35-3B8A3B33-2B13AB31-B16AB29-B18AB27-2B19A2B25-B2(20A2B24-2B)21A2B23-B22A2B22-2B23AB22-2B23A2B21-2B23A2B22-B23AB2(23-2B21A2B)24-B21AB25-B20A2B26-B19A2B27-B17A2B29-B15A2B30-3B12AB33-4B8A2B37-3B2A5B40-5B906-6B39-3B6A4B33-3B11A2B31-2B14A2B30-B16A2B28-B18A2B26-B20A2B24-B23AB22-2B23A2(B22-B24A)B21-2B25A3(B20-B26A)B20-2B2(25AB21-B)25AB21-2B23AB23-B23AB23-2B22AB24-2B20AB26-2B18AB28-B16A2B30-B14A2B32-3B10A2B34-4B5A4B38-7B810-3B41-4B3A5B34-2B12A2B31-B16AB29-B18AB27-2B19AB25-2B21AB23-2B23AB22-B24AB21-3(B26AB20-)B26AB19-2(B28AB18-)B28AB19-B27AB19-3(B26AB20-)2B25AB21-B24AB23-B23AB24-B21AB26-B19A2B27-B17A2B29-B15A2B31-B13AB34-4B4A5B39-4B762-8B37-3B8A3B32-2B14A2B29-B18AB27-B20AB25-B22AB23-B24AB22-B25A2(B20-B26A)B20-B27A3(B18-B28A)B18-2(B29AB17-)2(B28AB18-)B28AB19-B27AB19-B26AB20-B26AB21-B25AB22-B23AB24-B21AB26-B20AB27-B17A2B29-B15AB32-3B10A2B36-4BA5B42-B13-2C41-7C38-10C39-6C513-4B40-4B4A5B33-2B13AB30-2B16A2B27-B20AB25-B22AB23-B24AB22-B25AB20-B26AB19-4(B28AB18-)B29A4(B16-B30A)2(B17-B29A)B17-B28AB18-B28AB19-B27AB19-B26AB21-B25AB22-B23AB24-B21AB26-B19A2B27-B17AB30-2B13A2B33-4B6A3B10-C28-6B10-4C39-5C2A2C34-5C6A2C36-2C4A4C39-5C420-B43-4BA6B34-3B11A2B31-B16A2B27-2B19AB25-B22AB23-B24AB22-B25AB20-B26AB19-B28AB18-B29AB17-B29A3(B16-B30A)B16-4(B31AB15-)B30AB16-B30A3(B17-B29A)B18-B27AB20-B25AB21-B25AB22-B23AB24-B21AB26-2B18AB29-B15A2B31-2B12AB9-4C22-4B3A5B7-3CA3C26-3B8-4C4A2C31-7C6A2C33-2C7A4C36-8C417-7B37-4B7A4B31-2B15AB29-B18A2B25-2B21AB23-B24AB22-B25AB20-B26AB19-B28AB18-B29A2(B16-B30A)B16-B31AB15-B31A5(B14-B32A)3(B15-B31A)B15-B30A2(B17-B29A)B18-B27AB20-B26AB20-B25AB22-B23AB24-2B20A2B26-B18AB9-3C17-B15A2B7-3CA2C18-4B8A3B7-2C4AC23-8B6-4C4A2C29-C2A6C6A2C31-C11A3C34-11C413-11B34-3B11A2B30-2B16A2B27-B20A2B23-2B23AB22-B25AB20-B26AB19-B28AB18-B28AB17-2(B30AB16-)B31A4(B14-B32A)B13-B33AB14-B33AB13-3(B32AB14-)B32AB15-B31AB15-B30A2(B17-B29A)B18-B27AB20-B25AB21-B25AB22-2B22AB8-3C14-B19A2B8-C2AC15-B17AB8-2C3AC16-2B13A2B7-2C4AC19-6BAB3A2B6-3C4A2C26-B-C4A6C4A3C30-C12A2C34-3C4A5C39-4C325-2B41-5B2A6B32-3B13A2B29-B18AB26-2B20A2B23-B24AB21-B26AB20-B26AB19-B28AB17-B30AB16-B30AB15-5(B32AB14-)B33A2(B12-B34A)B13-B33AB13-3(B32AB14-)B32AB15-B31AB15-B30AB17-B29AB17-B28AB19-B27AB20-B25AB8-3C11-B23AB8-C2AC12-B21AB8-C3AC13-2B17A2B8-C3AC16-2B13A2B7-3C3AC19-5B7AB7-2C5AC25-3B4A8C4A3C28-C14A2C32-C9A4C35-9C322-4B39-5B4A5B32-2B14A2B28-2B18A2B25-B22AB23-B24AB21-B26AB19-B28AB18-B28AB17-B30AB16-B31A4(B14-B32A)B14-B33A3(B12-B34A)2(B13-B33A)B13-3(B32AB14-)B32AB15-B31AB16-B29AB17-B29AB18-B27AB9-3C8-B25AB9-CA2C8-B25AB8-C2AC10-2B21A2B8-C3AC12-2B18AB8-2C3AC15-B15A2B7-2C4AC17-5B8A2B7-2C5AC23-2B4A2C3-6C4A3C26-C5A3C8A2C30-2C10A4C34-10C320-6B37-5B6A5B31-B16A2B27-2B19AB25-B22A2B21-2B25AB20-B26AB19-B28AB18-B29AB16-B30AB15-4(B32AB14-)B33A5(B12-B34A)2(B13-B33A)B13-2(B32AB14-)B32AB15-B31AB15-B30AB17-B29AB9-3C6-B27AB9-C2AC6-B27AB8-C3AC7-B25AB8-C3AC9-2B22AB8-C3AC12-B19A2B8-C3AC14-2B15A2B7-3C3AC17-4B7A4B7-2C5AC22-3B3AB6-5C5A2C26-C3A6C7A3C29-2C10A4C34-10C319-8B36-4B8A4B30-2B16A2B27-B20A2B23-2B23AB21-B26AB20-B27AB18-B28AB17-B30AB16-B31A3(B14-B32A)B14-B33AB13-B33A6(B12-B34A)3(B13-B33A)B13-B32A2(B15-B31A)B9-3C4-B29AB9-C2AC5-B27AB9-C2AC6-B27AB8-C3AC7-B25AB8-C3AC9-B23A2B7-C4AC10-2B19A2B8-C4AC13-2B16AB8-2C4AC16-3B9A4B6-3C4A2C20-4B4AB6-4C5A2C26-C4A6C7A2C29-C12A4C32-12C317-10B35-3B10A4B29-2B17AB26-2B20A2B23-B24A2B20-B26AB20-B27AB18-B29AB16-B30AB16-B31AB14-B32AB14-2(B33AB13-)B33A3(B12-B34A)B12-2(B35AB11-)B34AB12-B34A4(B13-B33A)B14-B31AB10-2C3-B31AB9-CAC4-B29AB9-C2AC4-B29AB8-C3AC5-B27AB8-C3AC7-B25AB8-C4AC8-B23A2B7-C4AC10-2B20AB8-C4AC13-B17A2B7-2C4AC15-3B12A2B7-2C5AC19-4B6A2B5-4C5A2C24-C7A5C6A3C27-2C13A3C32-C6A6C36-6C43-5C46-2C177-12B33-3B12A3B29-B18A2B25-2B21AB23-B24A2B20-B27AB18-B28AB18-B29AB16-B30AB16-B31AB14-2(B33AB13-)B33A3(B12-B34A)B12-4(B35AB11-)B34AB12-B34A3(B13-B33A)B10-2C-B33AB9-CAC2-B31AB9-C2AC3-B29AB9-C3AC3-B29AB9-C2AC5-B27AB9-C2AC6-B27AB8-C3AC7-2B24AB8-C3AC10-B21A2B8-C3AC12-2B18AB8-2C3AC15-2B14A2B6-3C4AC18-5B8AB5-3C5A2C24-C8A5C5A3C27-C15A2C31-C8A6C34-C6AC41-2C4AC43-3CAC46-2C128-12B33-3B12A3B29-B18A2B25-2B21AB22-2B24A2B20-B27AB18-B28AB18-B29AB16-B30AB15-2(B32AB14-)B33A5(B12-B34A)B12-2(B35AB11-)3(B34AB12-)B34A2(B13-B33A)B10-2C-B32AB10-CAC2-B31AB9-C2AC2-B30AB9-C3AC3-B29AB9-C2AC5-B27AB9-C2AC6-B26AB9-C3AC7-B24A2B8-C3AC9-2B21AB9-C3AC12-2B17A2B8-2C3AC15-2B13A2B7-3C4AC18-5B7AB6-3C5A2C24-C7A6C5A3C26-C16A2C30-C9A6C33-C7AC40-2C6AC41-2C4AC43-5C128-11B34-3B11A3B29-2B17AB26-2B20A2B23-B24A2B20-B26AB19-B28AB18-B29AB16-B30AB16-B31AB14-B32AB14-B33AB13-B33A4(B12-B34A)B12-B35AB11-3(B34AB12-)B34A2(B13-B33A)B13-B32AB11-2C-B32AB10-CAC2-B31AB9-C2AC3-B29AB9-C2AC4-B28AB9-C3AC5-B27AB8-C3AC6-B26AB8-C4AC7-2B23A2B7-C4AC10-2B20AB8-C4AC13-B17A2B7-2C4AC15-3B11A3B7-2C5AC19-4B6AB6-4C5A2C24-C6A6C6A3C25-C16A3C29-C9A6C33-C5A3C40-2C6AC41-2C5A2C41-7C47-C80-9B35-4B9A4B29-2B17AB27-B20A2B23-2B23AB21-B26AB20-B27AB18-B28AB17-B30AB16-B31A2(B14-B32A)B14-B33AB13-B33A7(B12-B34A)2(B13-B33A)B13-B32AB14-B32AB15-B31AB11-C3-B31AB9-3C4-B29AB9-C2AC4-B28AB9-C2AC6-B27AB8-C3AC7-B25AB8-C3AC9-B23AB8-C4AC10-2B19A2B8-C4AC13-2B16AB8-2C4AC16-3B9A4B6-3C4A2C20-2B6AB6-4C5A2C24-C6A6C7A2C26-C16A3C29-C6A9C33-C4AC43-C4A3C41-2C5A4C39-4C4AC43-5C81-6B36-6B6A4B31-B16A2B27-2B19AB24-2B22A2B22-B25AB20-B27AB18-B28AB18-B29AB16-B30AB15-3(B32AB14-)2(B33AB13-)B33A4(B12-B34A)2(B13-B33A)B13-2(B32AB14-)B32AB15-B31AB16-B29AB11-C5-B29AB9-3C6-B27AB9-C2AC6-B27AB8-C2AC8-B25AB8-C3AC9-2B21A2B8-C3AC12-B19AB9-C3AC14-2B15A2B7-3C3AC17-4B7A4B7-2C5AC22-B5AB6-5C5A2C23-C6A6C7A3C25-C16A3C29-C6A9C33-C4AC43-2C3A3C42-2C4A5C39-3C6AC41-6C82-4B38-6B4A5B31-2B15A2B28-B19AB25-2B21A2B22-B25AB20-B26AB20-B27AB18-B29AB16-B30AB16-B31A3(B14-B32A)B14-2(B33AB13-)B33AB12-B34A4(B13-B33A)B13-B32AB14-B32A2(B15-B31A)B16-B29AB17-B29AB10-C7-B27AB9-3C8-B25AB9-C2AC8-B25AB8-C2AC10-2B21A2B8-C3AC12-2B18AB8-2C3AC15-B15A2B7-2C4AC17-5B6A4B7-2C5AC23-B4AC5-6C4A3C23-C2AC3A5C8A2C26-C3AC11A4C29-C3A11C34-C3AC44-C3A3C42-2C4A4C40-3C5A3C40-5CA2C45-C36-2B40-6B2A5B33-2B13A2B29-2B17A2B25-2B21AB23-B24A2B20-B26AB20-B27AB18-B28AB18-B29AB16-2(B31AB15-)B31AB14-B32AB14-7(B33AB13-)B32AB14-B32A3(B15-B31A)B16-B29AB18-B27AB19-B27AB10-C9-B25AB8-4C10-B23A2B7-C3AC11-2B20AB8-C3AC14-B17A2B8-C3AC16-2B14AB7-3C3AC19-5B7A2B6-2C5AC25-2B3A2C3-5C4A3C24-3C-C4A3C7A2C27-C2AC-2C8A4C30-C2AC2-8C35-C2A2C44-C3A3C42-2C4A3C41-2C5A5C38-4C4AC43-5C77-11B34-3B11A3B29-2B17AB27-B20A2B23-2B23AB22-B25AB20-B27AB19-B27AB18-B29AB16-3(B31AB15-)B31AB14-B32AB14-5(B33AB13-)B32A4(B15-B31A)B16-B29AB17-B29AB18-B27AB20-B25AB21-B25AB9-2C11-B23AB8-2CAC12-2B19A2B8-C2AC15-2B16AB8-2C2AC18-B13A2B7-2C4AC19-6B4A3B6-3C4A2C26-2B4A7C5A2C24-3C3-C12A3C26-C2AC3-3C4A5C30-C2A2C4-4C36-C3AC44-2C2A3C43-2C3A3C42-2C4A6C38-3C6AC41-7C77-10B35-3B10A2B31-2B15A2B28-B19AB25-2B21A2B22-B24AB22-B25AB20-B27AB18-B28AB18-B29AB16-B30AB16-2(B31AB15-)B31AB14-B32AB14-3(B33AB13-)B32A4(B15-B31A)B15-B30AB17-B29AB18-B27AB19-B26AB21-B25AB22-B23AB24-B21AB10-2C14-2B17A2B9-3C17-B15AB8-3C2AC18-4B7A4B7-2C4AC23-7B8-3C4A2C29-CA8C5A2C26-2C3-C11A3C27-C2AC3-11C31-C2A2C44-C3AC44-2C2A2C44-2C2A3C43-2C3A8C37-2C7AC40-8C79-5B39-4B5A4B33-2B13A2B30-B17AB27-2B19A2B24-B23AB22-B24AB22-B25AB20-B27AB18-B28AB18-B29AB17-B29AB16-B30AB16-2(B31AB15-)B31AB14-B32A3(B15-B31A)B15-B30A3(B17-B29A)B18-B27AB20-B25AB21-B25AB22-B23AB24-B21AB26-2B18AB29-B15A2B11-C19-2B11A2B9-5C21-5B2A4B8-3C3AC27-2B8-4C4A2C31-7C6A2C27-2C4-C8A4C29-CAC4-8C33-C2AC45-C2(2A2C44-2C)2A3C43-2C3A8C37-2C8AC39-9C124-9B36-3B9A3B32-B15AB29-2B17A2B26-B21AB24-B23AB23-B23AB22-B25AB20-B27AB19-B27AB18-3(B29AB17-)B29AB16-B30AB16-B31AB15-B31AB16-4(B29AB17-)B28AB19-B27AB20-B25AB21-B25AB22-B23AB24-B21AB26-B19A2B27-2B16AB31-B13A2B33-4B5A4B11-3C25-5B11-6C37-5C3AC34-5C6A2C35-2C4A5C30-3C6-4C35-C2AC45-C3(2A2C44-2C)2A9C37-2C8AC39-9C127-3B40-5B3A4B35-B12A3B31-B16AB28-2B18AB26-B21AB24-B23AB23-B24AB21-B25AB20-3(B27AB19-)B27AB18-4(B29AB17-)B29AB18-B28AB18-2(B27AB19-)B27AB20-B25AB21-B25AB22-B23AB24-B21AB26-B20AB27-B17A2B29-2B14AB33-2B9A3B36-9B57-4C39-5C2AC37-3C3A4C38-6C33-2C46-CA2C45-2CA2C45-C2A2C44-2C2A3C43-2C3A9C36-2C9AC38-9C173-7B38-3B7A4B33-B14AB30-2B16AB28-B19AB26-B21AB24-B23AB23-B24A2(B21-B25A)B20-4(B27AB19-)B28AB18-3(B27AB19-)B27AB20-B26AB20-B25AB21-B25AB22-B23AB24-B21AB26-B19AB28-B17A2B29-B15AB32-2B12AB35-4B4A4B40-4B103-6C39-5C82-C47-3C46-CA2C45-C2A2C44-2C2A3C43-2C3A9C36-3C8AC39-8C176-2B42-4B2A4B36-2B10A2B32-2B14AB30-2B16AB28-2B18AB26-2B20AB24-B23AB23-B23A2B3(21-B25AB)21-B26A3(B19-B27A)B20-B26AB20-2(B25AB21-)B25AB22-B23A2B22-B23AB24-B21AB26-B19AB28-B17AB30-B15AB32-B13AB34-3B7A3B38-7B283-C47-2C46-CA2C45-2CA3C44-C3A2C7-2C34-2C3A7CAC36-3C8AC39-8C223-4B40-4B4A3B36-2B9A3B33-B13A2B31-B15A2B29-B17A2B26-2B19A2B25-B21AB24-2B21A2B2(23-B23AB)22-B24A2B21-B25AB21-B25A2B20-B25AB21-B24A2(2B22-B23A)B23-2B21A2B24-B21AB25-2B19A2B26-2B17A2B28-2B16AB30-2B14AB32-2B10A3B34-5B4A4B38-7B380-2C46-CA2C45-C2A2C44-2C2A3C5-4C34-2C3A5C3AC36-3C7A2C39-7C271-4B41-9B37-4B5A4B34-2B11A2B32-2B14AB30-2B16AB28-2B18AB27-B19AB26-2B19A2B25-2B19A2B24-2B21AB24-2B21A2B23-B23AB23-2B21A2B23-2B21AB25-2B20AB25-2B19A2B26-B19AB27-2B18AB28-B17AB30-2B14AB32-2B11A3B33-3B7A4B35-6BA3B42-4B430-C47-3C46-CA3C44-2C2A3C3-5C35-2C3A3C4AC37-2C6A3C39-6C367-5B40-5B2A4B36-3B7A4B33-B13A2B31-2B14A2B29-2B15A2B29-2B16AB29-B17AB28-2B17A2B27-2B18AB26-2B19A2B26-2B18AB27-2B17A2B28-B17A2B28-2B16AB29-2B15A2B30-B15A2B30-2B13A2B33-2B9A3B35-5B3A3B39-7B45-B528-3C46-CA3C9-C34-2C2A10C36-2C9AC38-9C463-2B43-7B38-5B4A4B35-4B6A4B33-3B8A4B33-2B10A4B31-2B12A3B31-2B13A2B31-B15A2B29-2B15A2B30-B15A2B30-2B13A2B31-2B12A3B32-2B10A4B32-3B9A3B33-4B7A4B34-5B4A4B37-9B43-3B625-C47-4C7-4C34-C2A7C3AC35-3C8AC39-8C558-4B43-6B40-8B39-10B37-12B36-6B2A5B34-6B4A5B33-4B7A4B33-5B5A5B34-6B2A5B35-7BA4B37-10B39-9B40-7B43-4B771-13C35-2C10AC36-6C2A3C43-2C801-2B45-4B42-7B42-5B45-2B47-B925-4C37-7C3AC37-4C4A3C41-4C2015-3C42-7C41-4C158-
