model
name = "Untitled"
revision = 16
size = 7 14 12
origin = -y
shell = Outline 0.25
material type = toon, lighting = smooth, deform = 3 1
  colors = B:#E1FCF8 C:#F5B109 A:#000
material type = basic, lighting = smooth, roughness = 0, refractionRatio = 1, side = back
  colors = Outline:#000
voxels
------- ------- ------- ------- ------- ------- ------- ------- ------- ------- ------- ------- ------- ------- 
------- ------- ------- ------- ------- ------- ------- ------- ------- ------- ------- ------- ------- ------- 
------- ------- ------- ------- ------- ------- ------- ------- ------- ------- ------- ------- ------- ------- 
------- ------- ------- ------- ------- ------- ------- ------- ------- ------- ------- ------- ------- ------- 
------- ------- ------- ------- ------- ------- ------- ------- ------- ------- ------- ------- ------- ------- 
------- ------- ------- ------- ------- ------- ---B--- ---A--- ------- ------- ------- ------- ------- ------- 
------- ------- ------- ------- ------- ------- ---B--- ---B--- ------- ------- ------- ------- ------- -C----- 
------- ------- ------- ------- ------- ------- ---B--- ---B--- ---B--- ---B--- ---B--- ---B--- ---B--- -C-B--- 
------- ------- ------- ------- ------- ------- --BB--- --BB--- --BB--- --BB--- --BB--- --BB--- --BB--- -CBB--- 
------- ------- ------- ------- ------- ------- BBBB--- BBBB--- BBBB--- BBBB--- BBBB--- BBBB--- BBBB--- BBBB--- 
------- ------- ------- ------- ------- ------- BBBB--- BBBB--- BBBB--- BBBB--- BBBB--- BBBB--- BBBB--- BBBB--- 
------- ------- ------- ------- ------- ------- B------ B------ B------ B------ B------ B------ B------ B------ 
