model
name = hellosadlkfj
revision = 8405
size = 20 40 20
origin = -y
shell = Outline 0.25
material type = toon, lighting = smooth, deform = 1 1
  colors = C:#FFE3EC A:#620042
material type = basic, lighting = smooth, roughness = 0, refractionRatio = 1, side = back
  colors = Outline:#000
voxels
3(380-420C)380-5CA414C9(380-420C)380-8CA411C5(380-420C)380-9C8(A19C)2A18C2A2(19CA)38CA19C2A18CA19C2A39CA18CA30C
