model
name = main
revision = 2
size = 23 20 21
scale = 0.05
origin = -y
shell = Outline 0.25
material deform = 1 0.5
  colors = A:#C60 D:#888
material lighting = smooth, metalness = 1, deform = 1 1
  colors = C:#888
material 
  colors = B:#960
material type = basic, lighting = smooth, roughness = 0, refractionRatio = 1, side = back
  colors = Outline:#000
voxels
----------------------- ----------------------- ----------------------- ---------D---D--------- ----------------------- ----------------------- ----------------------- ----------------------- ----------------------- ----------------------- ----------------------- ----------------------- ----------------------- ----------------------- ----------------------- ----------------------- ----------------------- ----------------------- ----------------------- ----------------------- 
--AAAAAAAAAAAAAAAAAAAA- --AAAAAAAAAAAAAAAAAAAA- --AAAAAAAAAAAAAAAAAAAA- --AAA--------------AAA- --AAA--------------AAA- --AAA--------------AAA- --AAA--------------AAA- --AAA--------------AAA- --AAA--------------AAA- --AAA--------------AAA- --AAA--------------AAA- --ADA--------------DAA- --ADA--------------DAA- --AAA--------------AAA- --AAA--------------AAA- --AAA--------------AAA- --AAA--------------AAA- --AAAAAAAAAAAAAAAAAAAA- --AAAAAAAAAAAAAAAAAAAA- --AAAAAAAAAAAAAAAAAAAA- 
--AAAAAAAAAAAAAAAAAAAA- --ACBBBCB-CBBC-BCBBBCA- --AC-D-C--C--C--CD--CA- --DC---C--C--C--C---DA- --AC---C--C--C--C---CA- --AC---C--C--C--C---CA- --AC---C--C--C--C---CA- --AC---C--C--C--C---CA- --AC---C--C--C--C---CA- --AC---C--C--C--C---CA- --AC---C--C--C--C---CA- --AC---C--C--C--C---CA- --DC---C--C--C--C---DA- --AC---C--C--C--C---CA- --AC---C--C--C--C---CA- --AC---C--C--C--C---CA- --AC---C--C--C--C---CA- --AC---C--C--C--C---CA- --ACBBBCB-CBBC-BCBBBCA- --AAAAAAAAAAAAAAAAAAAA- 
--AAAAAAAAAAAAAAAAAAAA- --A-BBBBB-BBBB-BBBBB-A- --A---D---------D----A- --A------------------A- -DA------------------D- -DA------------------D- --A------------------A- --A------------------A- --A------------------A- --A------------------A- --A------------------A- --A------------------A- -DA------------------D- --A------------------A- --A------------------A- --A------------------A- --A------------------A- --A------------------A- --A-BBBBB-BBBB-BBBBB-A- --AAAAAAAAAAAAAAAAAAAA- 
--AAA--------------AAA- --A-BBBBB-BBBB-BBBBB-A- --A---D---------D----A- ----------------------- ----------------------- ----------------------- ----------------------- ----------------------- ----------------------- ----------------------- ----------------------- ----------------------- ----------------------- ----------------------- ----------------------- ----------------------- ----------------------- --A------------------A- --A-BBBBB-BBBB-BBBBB-A- --AAA--------------AAA- 
--AAA--------------AAA- --A-BBBBB-BBBB-BBBBB-A- --A------------------A- ----------------------- -D-------------------D- ----------------------- ----------------------- ----------------------- ----------------------- ----------------------- ----------------------- ----------------------- ----------------------- ----------------------- ----------------------- ----------------------- ----------------------- --A------------------A- --A-BBBBB-BBBB-BBBBB-A- --AAA--------------AAA- 
--AAA--------------AAA- --ACBBBBB-BBBB-BBBBBCA- --AC----------------CA- ---C----------------C-- --DC----------------D-- ---C----------------C-- DD-C----------------CDD ---C----------------C-- ---C----------------C-- ---C----------------C-- ---C----------------C-- --DC----------------D-- --DC----------------D-- ---C----------------C-- ---C----------------C-- ---C----------------C-- ---C----------------C-- --AC----------------CA- --ACBBBBB-BBBB-BBBBBCA- --AAA--------------AAA- 
--AAA--------------AAA- --A-BBBBB-BBBB-BBBBB-A- --A----D-------D-----A- ----------------------- ----------------------- ----------------------- ----------------------- ----------------------- ----------------------- ----------------------- ----------------------- ----------------------- ----------------------- ----------------------- ----------------------- ----------------------- ----------------------- --A------------------A- --A-BBBBB-BBBB-BBBBB-A- --AAA--------------AAA- 
--AAA--------------AAA- --A-BBBBB-BBBB-BBBBB-A- --A----D-------D-----A- ----------------------- ----------------------- -DD-----------------DD- -DD-----------------DD- ----------------------- --D-----------------D-- --D-----------------D-- --D-----------------D-- ----------------------- -D-------------------D- -D-------------------D- ----------------------- ----------------------- ----------------------- --A------------------A- --A-BBBBB-BBBB-BBBBB-A- --AAA--------------AAA- 
--AAA--------------AAA- --ACBBBBB-BBBB-BBBBBCA- --AC----------------CA- ---C----------------C-- ---C----------------C-- --DC----------------D-- -D-C----------------CD- --DC----------------D-- -D-C----------------CD- ---C----------------C-- ---C----------------C-- -DDC----------------DD- ---C----------------C-- ---C----------------C-- ---C----------------C-- ---C----------------C-- ---C----------------C-- --AC----------------CA- --ACBBBBB-BBBB-BBBBBCA- --AAA--------------AAA- 
--AAAAAAAAAAAAAAAAAAAA- --A-BBBBB-BBBB-BBBBB-A- --A------------------A- ----------------------- ----------------------- ----------------------- ----------------------- ----------------------- ----------------------- ----------------------- ----------------------- ----------------------- ----------------------- ----------------------- ----------------------- ----------------------- ----------------------- --A------------------A- --A-BBBBB-BBBB-BBBBB-A- --AAAAAAAAAAAAAAAAAAAA- 
--AAAAAAAAAAAAAAAAAAAA- --A-BBBBB-BBBB-BBBBB-A- --A------------------A- ----------------------- ----------------------- --D-----------------D-- -D-------------------D- --D-----------------D-- -D-------------------D- ----------------------- ----------------------- -DD-----------------DD- ----------------------- ----------------------- ----------------------- ----------------------- ----------------------- --A------------------A- --A-BBBBB-BBBB-BBBBB-A- --AAAAAAAAAAAAAAAAAAAA- 
--AAA--------------AAA- --ACBBBBB-BBBB-BBBBBCA- --AC---D-------D----CA- ---C----------------C-- ---C----------------C-- -DDC----------------DD- -DDC----------------DD- ---C----------------C-- --DC----------------D-- --DC----------------D-- --DC----------------D-- ---C----------------C-- -D-C----------------CD- -D-C----------------CD- ---C----------------C-- ---C----------------C-- ---C----------------C-- --AC----------------CA- --ACBBBBB-BBBB-BBBBBCA- --AAA--------------AAA- 
--AAA--------------AAA- --A-BBBBB-BBBB-BBBBB-A- --A----D-------D-----A- ----------------------- ----------------------- ----------------------- ----------------------- ----------------------- ----------------------- ----------------------- ----------------------- ----------------------- ----------------------- ----------------------- ----------------------- ----------------------- ----------------------- --A------------------A- --A-BBBBB-BBBB-BBBBB-A- --AAA--------------AAA- 
--AAA--------------AAA- --A-BBBBB-BBBB-BBBBB-A- --A------------------A- ----------------------- --D-----------------D-- ----------------------- DD-------------------DD ----------------------- ----------------------- ----------------------- ----------------------- --D-----------------D-- --D-----------------D-- ----------------------- ----------------------- ----------------------- ----------------------- --A------------------A- --A-BBBBB-BBBB-BBBBB-A- --AAA--------------AAA- 
--AAA--------------AAA- --ACBBBBB-BBBB-BBBBBCA- --AC----------------CA- ---C----------------C-- -D-C----------------CD- ---C----------------C-- ---C----------------C-- ---C----------------C-- ---C----------------C-- ---C----------------C-- ---C----------------C-- ---C----------------C-- ---C----------------C-- ---C----------------C-- ---C----------------C-- ---C----------------C-- ---C----------------C-- --AC----------------CA- --ACBBBBB-BBBB-BBBBBCA- --AAA--------------AAA- 
--AAA--------------AAA- --A-BBBBB-BBBB-BBBBB-A- --A---D---------D----A- ----------------------- ----------------------- ----------------------- ----------------------- ----------------------- ----------------------- ----------------------- ----------------------- ----------------------- ----------------------- ----------------------- ----------------------- ----------------------- ----------------------- --A------------------A- --A-BBBBB-BBBB-BBBBB-A- --AAA--------------AAA- 
--AAA--------------AAA- --A-BBBBB-BBBB-BBBBB-A- --A---D---------D----A- ----------------------- -D-------------------D- -D-------------------D- ----------------------- ----------------------- ----------------------- ----------------------- ----------------------- ----------------------- -D-------------------D- ----------------------- ----------------------- ----------------------- ----------------------- --A------------------A- --A-BBBBB-BBBB-BBBBB-A- --AAA--------------AAA- 
--AAAAAAAAAAAAAAAAAAAA- --A-BBBBB-BBBB-BBBBB-A- --A--D-----------D---A- --D-----------------DA- --A------------------A- --A------------------A- --A------------------A- --A------------------A- --A------------------A- --A------------------A- --A------------------A- --A------------------A- --D-----------------DA- --A------------------A- --A------------------A- --A------------------A- --A------------------A- --A------------------A- --A-BBBBB-BBBB-BBBBB-A- --AAAAAAAAAAAAAAAAAAAA- 
--AAAAAAAAAAAAAAAAAAAA- --ACBBBCB-CBBC-BCBBBCA- --AC---C--C--C--C---CA- --AC---C--C--C--C---CA- --AC---C--C--C--C---CA- --AC---C--C--C--C---CA- --AC---C--C--C--C---CA- --AC---C--C--C--C---CA- --AC---C--C--C--C---CA- --AC---C--C--C--C---CA- --AC---C--C--C--C---CA- --AD---C--C--C--C--DCA- --AD---C--C--C--C--DCA- --AC---C--C--C--C---CA- --AC---C--C--C--C---CA- --AC---C--C--C--C---CA- --AC---C--C--C--C---CA- --AC---C--C--C--C---CA- --ACBBBBB-BBBB-BBBBBCA- --AAAAAAAAAAAAAAAAAAAA- 
--AAAAAAAAAAAAAAAAAAAA- --AAAAAAAAAAAAAAAAAAAA- --AAAAAAAAAAAAAAAAAAAA- --AAA----D---D-----AAA- --AAA--------------AAA- --AAA--------------AAA- --AAA--------------AAA- --AAA--------------AAA- --AAA--------------AAA- --AAA--------------AAA- --AAA--------------AAA- --AAA--------------AAA- --AAA--------------AAA- --AAA--------------AAA- --AAA--------------AAA- --AAA--------------AAA- --AAA--------------AAA- --AAAAAAAAAAAAAAAAAAAA- --AAAAAAAAAAAAAAAAAAAA- --AAAAAAAAAAAAAAAAAAAA- 
