size = 20
scale = 0.05
origin = -y
material lighting = flat, deform = 1 0.5
  colors = A:#CC6600
material lighting = smooth, metalness = 1, deform = 1 1
  colors = C:#888888
material lighting = flat
  colors = B:#996600
voxels
63A13(14-6A)14-84AC3BCB-C2BC-BC3B16(C2AC3-3(C2-)C3-)C2AC3BCB-C2BC-BC3BC42A-5B-4B-5B-16(2A18-)2A-5B-4B-5B-24A2(14-4A-5B-4B-5B-2A18-A280-A18-2A-5B-4B-5B-4A14-6A)14-4AC5B-4B-5BC2AC16-CA-13(C16-C2-)C16-C-AC16-C2AC5B-4B-5BC2(4A14-6A14-4A-5B-4B-5B-2A18-A280-A18-2A-5B-4B-5B-)4A14-6A14-4AC5B-4B-5BC2AC16-CA-13(C16-C2-)C16-C-AC16-C2AC5B-4B-5BC4A14-24A-5B-4B-5B-2A18-A280-A18-2A-5B-4B-5B-42A-5B-4B-5B-2A18-A280-A18-2A-5B-4B-5B-24A14-4AC5B-4B-5BC2AC16-CA-13(C16-C2-)C16-C-AC16-C2AC5B-4B-5BC2(4A14-6A14-4A-5B-4B-5B-2A18-A280-A18-2A-5B-4B-5B-)4A14-6A14-4AC5B-4B-5BC2AC16-CA-13(C16-C2-)C16-C-AC16-C2AC5B-4B-5BC2(4A14-6A14-4A-5B-4B-5B-2A18-A280-A18-2A-5B-4B-5B-)4A14-24A-5B-4B-5B-16(2A18-)2A-5B-4B-5B-42AC3BCB-C2BC-BC3B16(C2AC3-3(C2-)C3-)C2AC5B-4B-5BC84A13(14-6A)14-63A