model
name = My New Object
revision = 29
size = 11 4 11
origin = -y
shell = Outline 0.25
material type = toon, lighting = smooth, deform = 1 1
  colors = B:#E12D39 A:#610316
material type = basic, lighting = smooth, roughness = 0, refractionRatio = 1, side = back
  colors = Outline:#000
voxels
----------- A---------A ----------- ----------- 
----------- ----------- ----------- ----------- 
----------- ----------- ----------- ----------- 
----------- ----------- ----------- ----------- 
----------- ----BBB---- ----BBB---- ----BBB---- 
----------- ----BBB---- ----BBB---- ----BBB---- 
----------- ----BBB---- ----BBB---- ----BBB---- 
----------- ----------- ----------- ----------- 
----------- ----------- ----------- ----------- 
----------- ----------- ----------- ----------- 
----------- A---------A ----------- ----------- 
