model
name = My New Object
revision = 54
size = 19 14 21
origin = -y
shell = Outline 0.25
material type = toon, lighting = smooth, deform = 1 1
  colors = A:#610316
material type = basic, lighting = smooth, roughness = 0, refractionRatio = 1, side = back
  colors = Outline:#000
voxels
------------------- ------------------- ------------------- ------------------- ------------------- ------------------- -A---------------A- -A---------------A- -A---------------A- -A---------------A- -A---------------A- -A---------------A- -A---------------A- -A---------------A- 
------------------- ------------------- ------------------- ------------------- ------------------- ------------------- AAAAAAAAAAAAAAAAAAA AAAAAAAAAAAAAAAAAAA AAAAAAAAAAAAAAAAAAA AAAAAAAAAAAAAAAAAAA AAAAAAAAAAAAAAAAAAA AAAAAAAAAAAAAAAAAAA AAAAAAAAAAAAAAAAAAA AAAAAAAAAAAAAAAAAAA 
------------------- ------------------- ------------------- ------------------- ------------------- ------------------- A-----------------A A-----------------A A-----------------A A-----------------A A-----------------A A-----------------A A-----------------A A-----------------A 
------------------- ------------------- ------------------- ------------------- ------------------- ------------------- A-----------------A A-----------------A A-----------------A A-----------------A A-----------------A A-----------------A A-----------------A A-----------------A 
------------------- ------------------- ------------------- ------------------- ------------------- ------------------- A-----------------A A-----------------A A-----------------A A-----------------A A-----------------A A-----------------A A-----------------A A-----------------A 
------------------- ------------------- ------------------- ------------------- ------------------- ------------------- A-----------------A A-----------------A A-----------------A A-----------------A A-----------------A A-----------------A A-----------------A A-----------------A 
------------------- ------------------- ------------------- ------------------- ------------------- ------------------- A-----------------A A-----------------A A-----------------A A-----------------A A-----------------A A-----------------A A-----------------A A-----------------A 
------------------- ------------------- ------------------- ------------------- ------------------- ------------------- A-----------------A A-----------------A A-----------------A A-----------------A A-----------------A A-----------------A A-----------------A A-----------------A 
------------------- ------------------- ------------------- ------------------- ------------------- ------------------- A-----------------A A-----------------A A-----------------A A-----------------A A-----------------A A-----------------A A-----------------A A-----------------A 
------------------- ------------------- ------------------- ------------------- ------------------- ------------------- A-----------------A A-----------------A A-----------------A A-----------------A A-----------------A A-----------------A A-----------------A A-----------------A 
------------------- ------------------- ------------------- ------------------- ------------------- ------------------- A-----------------A A-----------------A A-----------------A A-----------------A A-----------------A A-----------------A A-----------------A A-----------------A 
------------------- ------------------- ------------------- ------------------- ------------------- ------------------- A-----------------A A-----------------A A-----------------A A-----------------A A-----------------A A-----------------A A-----------------A A-----------------A 
------------------- ------------------- ------------------- ------------------- ------------------- ------------------- A-----------------A A-----------------A A-----------------A A-----------------A A-----------------A A-----------------A A-----------------A A-----------------A 
------------------- ------------------- ------------------- ------------------- ------------------- ------------------- A-----------------A A-----------------A A-----------------A A-----------------A A-----------------A A-----------------A A-----------------A A-----------------A 
------------------- ------------------- ------------------- ------------------- ------------------- ------------------- A-----------------A A-----------------A A-----------------A A-----------------A A-----------------A A-----------------A A-----------------A A-----------------A 
------------------- ------------------- ------------------- ------------------- ------------------- ------------------- A-----------------A A-----------------A A-----------------A A-----------------A A-----------------A A-----------------A A-----------------A A-----------------A 
------------------- ------------------- ------------------- ------------------- ------------------- ------------------- A-----------------A A-----------------A A-----------------A A-----------------A A-----------------A A-----------------A A-----------------A A-----------------A 
------------------- ------------------- ------------------- ------------------- ------------------- ------------------- A-----------------A A-----------------A A-----------------A A-----------------A A-----------------A A-----------------A A-----------------A A-----------------A 
------------------- ------------------- ------------------- ------------------- ------------------- ------------------- A-----------------A A-----------------A A-----------------A A-----------------A A-----------------A A-----------------A A-----------------A A-----------------A 
------------------- ------------------- ------------------- ------------------- ------------------- ------------------- AAAAAAAAAAAAAAAAAAA AAAAAAAAAAAAAAAAAAA AAAAAAAAAAAAAAAAAAA AAAAAAAAAAAAAAAAAAA AAAAAAAAAAAAAAAAAAA AAAAAAAAAAAAAAAAAAA AAAAAAAAAAAAAAAAAAA AAAAAAAAAAAAAAAAAAA 
------------------- ------------------- ------------------- ------------------- ------------------- ------------------- -A---------------A- -A---------------A- -A---------------A- -A---------------A- -A---------------A- -A---------------A- -A---------------A- -A---------------A- 
