model
name = My New Object
revision = 71
size = 19 18 21
origin = -y
shell = Outline 0.25
material type = toon, lighting = smooth, deform = 1 1
  colors = E:#FF9B9B A:#610316 D:#FFE3E3
material type = basic, lighting = smooth, roughness = 0, refractionRatio = 1, side = back
  colors = Outline:#000
voxels
------------------- ------------------- ------------------- ------------------- ------------------- ------------------- ------------------- ------------------- -A---------------A- -A---------------A- -A---------------A- -A---------------A- -A---------------A- -A---------------A- -A---------------A- -A---------------A- ------------------- ------------------- 
------------------- ------------------- ------------------- ------------------- ------------------- ------------------- ------------------- ------------------- AAAAAAAAAAAAAAAAAAA AAAAAAAAAAAAAAAAAAA AAAAAAAAAAAAAAAAAAA AAAAAAAAAAAAAAAAAAA AAAAAAAAAAAAAAAAAAA AAAAAAAAAAAAAAAAAAA AAAAAAAAAAAAAAAAAAA AAAAAAAAAAAAAAAAAAA ------------------- ------------------- 
------------------- ------------------- ------------------- ------------------- ------------------- ------------------- ------------------- ------------------- ADEEEEEEEEEE-----DA ADEEEEE----------DA AD---------------DA AD---------------DA AD---------------DA AD---------------DA AD---------------DA A-----------------A ------------------- ------------------- 
------------------- ------------------- ------------------- ------------------- ------------------- ------------------- ------------------- ------------------- A-EEEEEEEEEE------A A-EEEEE-----------A A--EEE------------A A--EEE------------A A--EEE------------A A--EEE------------A A--EEE------------A A--EEE------------A ---EEE------------- ---EEE------------- 
------------------- ------------------- ------------------- ------------------- ------------------- ------------------- ------------------- ------------------- A-EEEEEEEEEE------A A-EEEEE-----------A A--EEE------------A A--EEE------------A A--EEE------------A A--EEE------------A A--EEE------------A A--EEE------------A ---EEE------------- ---EEE------------- 
------------------- ------------------- ------------------- ------------------- ------------------- ------------------- ------------------- ------------------- A-EEEEEEEEEE------A A-EEEEE-----------A A--EEE------------A A--EEE------------A A--EEE------------A A--EEE------------A A--EEE------------A A--EEE------------A ---EEE------------- ---EEE------------- 
------------------- ------------------- ------------------- ------------------- ------------------- ------------------- ------------------- ------------------- A-EEEEEEEEEE------A A-EEEEE-----------A A--EEE------------A A--EEE------------A A--EEE------------A A--EEE------------A A--EEE------------A A--EEE------------A ---EEE------------- ---EEE------------- 
------------------- ------------------- ------------------- ------------------- ------------------- ------------------- ------------------- ------------------- A-EEEEEEEEEE------A A-EEEEE-----------A A--EEE------------A A--EEE------------A A--EEE------------A A--EEE------------A A--EEE------------A A--EEE------------A ---EEE------------- ---EEE------------- 
------------------- ------------------- ------------------- ------------------- ------------------- ------------------- ------------------- ------------------- A-EEEEEEEEEE------A A-EEEEE-----------A A--EEE------------A A--EEE------------A A--EEE------------A A--EEE------------A A--EEE------------A A--EEE------------A ---EEE------------- ---EEE------------- 
------------------- ------------------- ------------------- ------------------- ------------------- ------------------- ------------------- ------------------- A-EEEEEEEEEE------A A-EEEEE-----------A A--EEE------------A A--EEE------------A A--EEE------------A A--EEE------------A A--EEE------------A A--EEE------------A ---EEE------------- ---EEE------------- 
------------------- ------------------- ------------------- ------------------- ------------------- ------------------- ------------------- ------------------- A-EEEEEEEEEE------A A-EEEEE-----------A A--EEE------------A A--EEE------------A A--EEE------------A A--EEE------------A A--EEE------------A A--EEE------------A ---EEE------------- ---EEE------------- 
------------------- ------------------- ------------------- ------------------- ------------------- ------------------- ------------------- ------------------- A-EEEEEEEEEE------A A-EEEEE-----------A A--EEE------------A A--EEE------------A A--EEE------------A A--EEE------------A A--EEE------------A A--EEE------------A ---EEE------------- ---EEE------------- 
------------------- ------------------- ------------------- ------------------- ------------------- ------------------- ------------------- ------------------- A-EEEEEEEEEE------A A-EEEEE-----------A A--EEE------------A A--EEE------------A A--EEE------------A A--EEE------------A A--EEE------------A A--EEE------------A ---EEE------------- ---EEE------------- 
------------------- ------------------- ------------------- ------------------- ------------------- ------------------- ------------------- ------------------- A-EEEEEEEEEE------A A-EEEEE-----------A A--EEE------------A A--EEE------------A A--EEE------------A A--EEE------------A A--EEE------------A A--EEE------------A ---EEE------------- ---EEE------------- 
------------------- ------------------- ------------------- ------------------- ------------------- ------------------- ------------------- ------------------- A-EEEEEEEEEE------A A-EEEEE-----------A A--EEE------------A A--EEE------------A A--EEE------------A A--EEE------------A A--EEE------------A A--EEE------------A ---EEE------------- ---EEE------------- 
------------------- ------------------- ------------------- ------------------- ------------------- ------------------- ------------------- ------------------- A-EEEEEEEEEE------A A-EEEEE-----------A A--EEE------------A A--EEE------------A A--EEE------------A A--EEE------------A A--EEE------------A A--EEE------------A ---EEE------------- ---EEE------------- 
------------------- ------------------- ------------------- ------------------- ------------------- ------------------- ------------------- ------------------- A-EEEEEEEEEE------A A-EEEEE-----------A A--EEE------------A A--EEE------------A A--EEE------------A A--EEE------------A A--EEE------------A A--EEE------------A ---EEE------------- ---EEE------------- 
------------------- ------------------- ------------------- ------------------- ------------------- ------------------- ------------------- ------------------- A-EEEEEEEEEE------A A-EEEEE-----------A A--EEE------------A A--EEE------------A A--EEE------------A A--EEE------------A A--EEE------------A A--EEE------------A ---EEE------------- ---EEE------------- 
------------------- ------------------- ------------------- ------------------- ------------------- ------------------- ------------------- ------------------- ADEEEEEEEEEE-----DA ADEEEEE----------DA AD---------------DA AD---------------DA AD---------------DA AD---------------DA AD---------------DA A-----------------A ------------------- ------------------- 
------------------- ------------------- ------------------- ------------------- ------------------- ------------------- ------------------- ------------------- AAAAAAAAAAAAAAAAAAA AAAAAAAAAAAAAAAAAAA AAAAAAAAAAAAAAAAAAA AAAAAAAAAAAAAAAAAAA AAAAAAAAAAAAAAAAAAA AAAAAAAAAAAAAAAAAAA AAAAAAAAAAAAAAAAAAA AAAAAAAAAAAAAAAAAAA ------------------- ------------------- 
------------------- ------------------- ------------------- ------------------- ------------------- ------------------- ------------------- ------------------- -A---------------A- -A---------------A- -A---------------A- -A---------------A- -A---------------A- -A---------------A- -A---------------A- -A---------------A- ------------------- ------------------- 
