model
name = My New Object
revision = 86
size = 19 20 21
origin = -y
shell = Outline 0.25
material type = toon, lighting = smooth, deform = 1 1
  colors = E:#FF9B9B A:#610316 F:#3A66DB G:#88B1FC D:#FFE3E3
material type = basic, lighting = smooth, roughness = 0, refractionRatio = 1, side = back
  colors = Outline:#000
voxels
------------------- ------------------- ------------------- ------------------- ------------------- ------------------- ------------------- ------------------- ------------------- -A---------------A- -A---------------A- -A---------------A- -A---------------A- -A---------------A- -A---------------A- -A---------------A- -A---------------A- ------------------- ------------------- ------------------- 
------------------- ------------------- ------------------- ------------------- ------------------- ------------------- ------------------- ------------------- ------------------- AAAAAAAAAAAAAAAAAAA AAAAAAAAAAAAAAAAAAA AAAAAAAAAAAAAAAAAAA AAAAAAAAAAAAAAAAAAA AAAAAAAAAAAAAAAAAAA AAAAAAAAAAAAAAAAAAA AAAAAAAAAAAAAAAAAAA AAAAAAAAAAAAAAAAAAA ------------------- ------------------- ------------------- 
------------------- ------------------- ------------------- ------------------- ------------------- ------------------- ------------------- ------------------- ------------------- ADEEEEEEEEEE-----DA ADEEEEE----------DA AD---------------DA AD---------------DA AD---------------DA AD---------------DA AD---------------DA A-----------------A ------------------- ------------------- ------------------- 
------------------- ------------------- ------------------- ------------------- ------------------- ------------------- ------------------- ------------------- ------------------- A-EEEEEEEEEE------A A-EEEEE-----------A A--EEE------------A A--EEE------------A A--EEE------------A A--EEE------------A A--EEE------------A A--EEE------------A ---EEE------------- ---EEE------------- ------------------- 
------------------- ------------------- ------------------- ------------------- ------------------- ------------------- ------------------- ------------------- ------------------- A-EEEEEEEEEE------A A-EEEEE-----------A A--EEE------------A A--EEEF-----------A A--EEEF-----------A A--EEEF-----------A A--EEEF------------ A--EEEF------------ ---EEEF------------ ---EEE------------- ------------------- 
------------------- ------------------- ------------------- ------------------- ------------------- ------------------- ------------------- ------------------- ------------------- A-EEEEEEEEEE------A A-EEEEE-----------A A--EEE------------A A--EEEF-----------A A--EEEFG----------A A--EEEFG----------A A--EEEFG----------- A--EEEFG----------- ---EEEF------------ ---EEE------------- ------------------- 
------------------- ------------------- ------------------- ------------------- ------------------- ------------------- ------------------- ------------------- ------------------- A-EEEEEEEEEE------- A-EEEEE------------ A--EEE------------- A--EEEF------------ A--EEEFG----------- A--EEEFGG---------- A--EEEFGG---------- A--EEEFGG---------- ---EEEF------------ ---EEE------------- ------------------- 
------------------- ------------------- ------------------- ------------------- ------------------- ------------------- ------------------- ------------------- ------------------- A-EEEEEEEEEE------- A-EEEEE------------ A--EEE------------- A--EEEF------------ A--EEEFG----------- A--EEEFGG---------- A--EEEFGG---------- A--EEEFGG---------- ---EEEF------------ ---EEE------------- ------------------- 
------------------- ------------------- ------------------- ------------------- ------------------- ------------------- ------------------- ------------------- ------------------- A-EEEEEEEEEE------- A-EEEEE------------ A--EEE------------- A--EEEF------------ A--EEEFG----------- A--EEEFG----------- A--EEEFG----------- A--EEEFG----------- ---EEEF------------ ---EEE------------- ------------------- 
------------------- ------------------- ------------------- ------------------- ------------------- ------------------- ------------------- ------------------- ------------------- A-EEEEEEEEEE------- A-EEEEE------------ A--EEE------------- A--EEEF------------ A--EEEF------------ A--EEEF------------ A--EEEF------------ A--EEEF------------ ---EEEF------------ ---EEE------------- ------------------- 
------------------- ------------------- ------------------- ------------------- ------------------- ------------------- ------------------- ------------------- ------------------- A-EEEEEEEEEE------- A-EEEEE------------ A--EEE------------- A--EEEFG----------- A--EEEFGG---------- A--EEEFGG---------- A--EEEFGG---------- A--EEEF------------ ---EEEF------------ ---EEE------------- ------------------- 
------------------- ------------------- ------------------- ------------------- ------------------- ------------------- ------------------- ------------------- ------------------- A-EEEEEEEEEE------- A-EEEEE------------ A--EEE------------- A--EEEFG----------- A--EEEFGG---------- A--EEEFGG---------- A--EEEFGG---------- A--EEEF------------ ---EEEF------------ ---EEE------------- ------------------- 
------------------- ------------------- ------------------- ------------------- ------------------- ------------------- ------------------- ------------------- ------------------- A-EEEEEEEEEE------- A-EEEEE------------ A--EEE------------- A--EEEF------------ A--EEEFG----------- A--EEEFG----------- A--EEEFG----------- A--EEEFG----------- ---EEEF------------ ---EEE------------- ------------------- 
------------------- ------------------- ------------------- ------------------- ------------------- ------------------- ------------------- ------------------- ------------------- A-EEEEEEEEEE------- A-EEEEE------------ A--EEE------------- A--EEEF------------ A--EEEFG----------- A--EEEFGG---------- A--EEEFGG---------- A--EEEFGG---------- ---EEEF------------ ---EEE------------- ------------------- 
------------------- ------------------- ------------------- ------------------- ------------------- ------------------- ------------------- ------------------- ------------------- A-EEEEEEEEEE------- A-EEEEE------------ A--EEE------------- A--EEEF------------ A--EEEFG----------- A--EEEFGG---------- A--EEEFGG---------- A--EEEFGG---------- ---EEEF------------ ---EEE------------- ------------------- 
------------------- ------------------- ------------------- ------------------- ------------------- ------------------- ------------------- ------------------- ------------------- A-EEEEEEEEEE------A A-EEEEE-----------A A--EEE------------A A--EEEF-----------A A--EEEFG----------A A--EEEFG----------A A--EEEFG----------- A--EEEFG----------- ---EEEF------------ ---EEE------------- ------------------- 
------------------- ------------------- ------------------- ------------------- ------------------- ------------------- ------------------- ------------------- ------------------- A-EEEEEEEEEE------A A-EEEEE-----------A A--EEE------------A A--EEEF-----------A A--EEEF-----------A A--EEEF-----------A A--EEEF------------ A--EEEF------------ ---EEEF------------ ---EEE------------- ------------------- 
------------------- ------------------- ------------------- ------------------- ------------------- ------------------- ------------------- ------------------- ------------------- A-EEEEEEEEEE------A A-EEEEE-----------A A--EEE------------A A--EEE------------A A--EEE------------A A--EEE------------A A--EEE------------A A--EEE------------A ---EEE------------- ---EEE------------- ------------------- 
------------------- ------------------- ------------------- ------------------- ------------------- ------------------- ------------------- ------------------- ------------------- ADEEEEEEEEEE-----DA ADEEEEE----------DA AD---------------DA AD---------------DA AD---------------DA AD---------------DA AD---------------DA A-----------------A ------------------- ------------------- ------------------- 
------------------- ------------------- ------------------- ------------------- ------------------- ------------------- ------------------- ------------------- ------------------- AAAAAAAAAAAAAAAAAAA AAAAAAAAAAAAAAAAAAA AAAAAAAAAAAAAAAAAAA AAAAAAAAAAAAAAAAAAA AAAAAAAAAAAAAAAAAAA AAAAAAAAAAAAAAAAAAA AAAAAAAAAAAAAAAAAAA AAAAAAAAAAAAAAAAAAA ------------------- ------------------- ------------------- 
------------------- ------------------- ------------------- ------------------- ------------------- ------------------- ------------------- ------------------- ------------------- -A---------------A- -A---------------A- -A---------------A- -A---------------A- -A---------------A- -A---------------A- -A---------------A- -A---------------A- ------------------- ------------------- ------------------- 
