model
name = My New Object
revision = 1
size = 3 4 3
origin = -y
shell = Outline 0.25
material type = toon, lighting = smooth, deform = 1 1
  colors = B:#E12D39
material type = basic, lighting = smooth, roughness = 0, refractionRatio = 1, side = back
  colors = Outline:#000
voxels
--- BBB BBB BBB 
--- BBB BBB BBB 
--- BBB BBB BBB 
