model
name = main
size = 16 3 16
scale = 0.05
origin = -y
material type = toon, lighting = smooth, deform = 1 1 
  colors = A:#A32858 B:#CC425E
voxels
AAAAAAAAAAAAAAAA AAAAAAAAAAAAAAAA AAAAAAAAAAAAAAAA 
AA--AAA--AAA--AA AABBAAABBAAABBAA AA--AAA--AAA--AA 
A----A----A----A ABBBBABBBBABBBBA A----A----A----A 
A----A----A----A ABBBBABBBBABBBBA A----A----A----A 
AA---A----A---AA AABBBABBBBABBBAA AA---A----A---AA 
AAAAAAAAAAAAAAAA AAAAAAAAAAAAAAAA AAAAAAAAAAAAAAAA 
AA---A----A---AA AABBBABBBBABBBAA AA---A----A---AA 
A----A----A----A ABBBBABBBBABBBBA A----A----A----A 
A----A----A----A ABBBBABBBBABBBBA A----A----A----A 
AA---A----A---AA AABBBABBBBABBBAA AA---A----A---AA 
AAAAAAAAAAAAAAAA AAAAAAAAAAAAAAAA AAAAAAAAAAAAAAAA 
AA---A----A---AA AABBBABBBBABBBAA AA---A----A---AA 
A----A----A----A ABBBBABBBBABBBBA A----A----A----A 
A----A----A----A ABBBBABBBBABBBBA A----A----A----A 
AA--AAA--AAA--AA AABBAAABBAAABBAA AA--AAA--AAA--AA 
AAAAAAAAAAAAAAAA AAAAAAAAAAAAAAAA AAAAAAAAAAAAAAAA 
