model
name = main
size = 14
scale = 0.05
origin = -y
material type = toon, lighting = smooth, deform = 1 1 
  colors = A:#6BC96C B:#5BA675 C:#ABDD64 D:#FCEF8D
voxels
-BBBBBBBBBBBB- -------------- -------------- -------------- -------------- -------------- -------------- -------------- -------------- -------------- -------------- -------------- -------------- -------------- 
BBBAAAAAAAABBB ---BBBBBBBB--- ---BAAAAAAB--- ---BAAAAAAB--- ---BAAACCAB--- ---BAACCCAB--- ---BACCCCAB--- ---BACCCCAB--- ---BACCCAAB--- ---BAAAAAAB--- ----BAAAAB---- -------------- -------------- -------------- 
BBAAAAAAAAAABB --BAAAAAAAAB-- --BAAAAAAAAB-- --BAAAAAAAAB-- --BAAAAAAAAB-- --BAAAAAAAAB-- --BAAAAAAAAB-- --BAAAAAAAAB-- --BAAAAAAAAB-- --BAAAAAAAAB-- --BBAAAAAABB-- ---BBBAABBB--- -------------- -------------- 
BAAAAAAAAAAAAB -BAAAAAAAAAAB- -BAAAAAAAAAAB- -AAAAAAAAAAAA- -AAAAAAAAAAAA- -AAAAAAAAAAAA- -AAAAAAAAAAAA- -AAAAAAAAAAAA- -AAAAAAAAAAAA- -BAAAAAAAAAAB- --BAAAAAAAAB-- --BBAAAAAABB-- ----BBBBBB---- -------------- 
BAAAAAAAAAAAAB -BAAAAAAAAAAB- -AAAAAAAAAAAA- -AAAAAAAAAAAA- -AAAAAAAAAAAA- -AAAAAAAAAAAC- -BAAAAAAAAAAC- -BAAAAAAAAAAA- -DAAAAAAAAAAA- -AAAAAAAAAAAA- -BAAAAAAAAAAB- --BAAAAAAAAB-- ---BBAAAABB--- -----AAAA----- 
BAAAAAAAAAAAAB -BAAAAAAAAAAB- -AAAAAAAAAAAA- -AAAAAAAAAAAC- -CAAAAAAAAAAC- -CAAAAAAAAAAC- -AAAAAAAAAAAC- -AAAAAAAAAAAC- -AAAAAAAAAAAC- -AAAAAAAAAAAA- -AAAAAAAAAAAA- --BAAAAAAAAB-- ---BAAAAAAB--- ----ACCCCA---- 
BAAAAAAAAAAAAB -BAAAAAAAAAAB- -AAAAAAAAAAAA- -CAAAAAAAAAAC- -CAAAAAAAAAAC- -CAAAAAAAAAAC- -CAAAAAAAAAAC- -CAAAAAAAAAAC- -CAAAAAAAAAAC- -AAAAAAAAAAAA- -AAAAAAAAAAAA- --AAAAAAAAAA-- ---BAAAAAAB--- ----ACCCCA---- 
BAAAAAAAAAAAAB -BAAAAAAAAAAB- -AAAAAAAAAAAA- -CAAAAAAAAAAC- -CAAAAAAAAAAC- -CAAAAAAAAAAC- -CAAAAAAAAAAC- -CAAAAAAAAAAC- -CAAAAAAAAAAC- -AAAAAAAAAAAA- -AAAAAAAAAAAA- --AAAAAAAAAA-- ---BAAAAAAB--- ----ACCCCA---- 
BAAAAAAAAAAAAB -BAAAAAAAAAAB- -AAAAAAAAAAAA- -AAAAAAAAAAAA- -CAAAAAAAAAAC- -CAAAAAAAAAAC- -AAAAAAAAAAAC- -AAAAAAAAAAAC- -AAAAAAAAAAAC- -AAAAAAAAAAAA- -AAAAAAAAAAAA- --BAAAAAAAAB-- ---BAAAAAAB--- ----ACCCCA---- 
BAAAAAAAAAAAAB -BAAAAAAAAAAB- -AAAAAAAAAAAA- -AAAAAAAAAAAA- -AAAAAAAAAAAA- -AAAAAAAAAAAA- -BAAAAAAAAAAA- -BAAAAAAAAAAA- -DAAAAAAAAAAA- -AAAAAAAAAAAA- -BAAAAAAAAAAB- --BAAAAAAAAB-- ---BBAAAABB--- -----AAAA----- 
BAAAAAAAAAAAAB -BAAAAAAAAAAB- -BAAAAAAAAAAB- -AAAAAAAAAAAA- -AAAAAAAAAAAA- -AAAAAAAAAAAA- -AAAAAAAAAAAA- -AAAAAAAAAAAA- -AAAAAAAAAAAA- -BAAAAAAAAAAB- --BAAAAAAAAB-- --BBAAAAAABB-- ----BBBBBB---- -------------- 
BBAAAAAAAAAABB --BAAAAAAAAB-- --BAAAAAAAAB-- --BAAAAAAAAB-- --BAAAAAAAAB-- --BAAAAAAAAB-- --BAAAAAAAAB-- --BAAAAAAAAB-- --BAAAAAAAAB-- --BAAAAAAAAB-- --BBAAAAAABB-- ---BBBAABBB--- -------------- -------------- 
BBBAAAAAAAABBB ---BBBBBBBB--- ---BAAAAAAB--- ---BAAAAAAB--- ---BACCCCAB--- ---BACCCCAB--- ---BACCCAAB--- ---BACCCAAB--- ---BACCCAAB--- ---BAAAAAAB--- ----BAAAAB---- -------------- -------------- -------------- 
-BBBBBBBBBBBB- -------------- -------------- -------------- -------------- -------------- -------------- -------------- -------------- -------------- -------------- -------------- -------------- -------------- 
