model
name = main
size = 24 80 34
scale = 0.05
origin = -y
shell = Outline 0.25
material type = toon, lighting = smooth, deform = 1 1
  colors = A:#877553 B:#615442 C:#48332B D:#C1A771 E:#35241D F:#6F3924 G:#A85C3E H:#BE8E17 I:#48251C J:#FF9B9B
material type = basic, lighting = smooth, roughness = 0, refractionRatio = 1, side = back
  colors = Outline:#000
voxels
12-3B21-3B1888-10A19-3B1888-10A1910-8ABA16-3B1891-7AB2A16-3B559-2(C23-)C1283-A9B578-C47-C1283-9AB14-B7ABA554-C47-C822-4(H-)H2-4(H-)H4-4(F-)F2-4(F-)F4-4(FI)F2-4(FI)F4-9C2-9C369-9AB14-10A15-A6-A507-C23-E23-J23-E23-C391-7C4-7C461-9C2-9C369-A8DB14-10A15-A3-3BA579-C270-9C2-9C4(4-4(C-)C2-4(C-)C)4-C3(-E)-C2-C3(-E)-C4-9C2-9C460-9C2-9C369-A8DB14-10A15-A3-3BA16-A6-A555-C270-9C2-9C5(4-C7-C2-C7-C)4-E7-E2-E7-E17(4-C7-C2-C7-C)4-E7-C2-C7-E4-E7-E2-E7-E4-9C2-9C363-6D10A6D8-2AB7A15-A6-A16-A6-A13-D2-D6-D2-D13-D6-D13-2(D2-D6-D2-D10-)D2-D6-D2-D8-D-D2-D6-D2-D-D8-D2-D6-D2-D8-2(D-D2-D6-D2-D-D6-)D-D2-D6-D2-D-D7-2D2-D6-D2-2D12-11(D6-D16-)D6-D3-E12-D6-D16-3D2-3D18-D2-D20-4D156-2E5-2E2-2E5-2E4-9C2-9C124-C7-C2-C7-C460-C7EC2-C7EC269-4(2C2-)2C6-4(2C2-)2C51-7D10A7D-2(6B2A)6B2-B5ABA6-ABA2B2AB2-2B2A3BA6-ABA2B3A2-B3A3BA6-ABA2B2AB2(2-4AD2BA6-ABA2B3A)2-AB2AD2BA6-ABA2B3A2(2-4A3BA6-ABA4BA)2-2ABA3BA6-ABA4B2(A2-4A3BA6-ABA2BAB)A2-3A4BA6-AB2A2(BA)2-6ABA6-AB6A2-6ABA6-AB4ABD2-D5ABA6-AB5AD2-7DA6-A7D2-2D-D-2DA6-A2D-D-2D8-4(DA6-AD14-)DA6-AD15-A6-A9-3B3-DA6-AD2-E5-3B3-DA6-AD-3C11-A6-A9-5B-D3A2-3AD8-5B2(2-3A)9-5B4-4A11-5B4-4A28-2(5B3-2C5-2C2-2C3-)5B3-CE5-EC2-CE3-5B3-2E5-2E2-2E5-2E4-2C5E2C2-2C5E2C4-E7CE2-E7CE5(4-C7-C2-C7-C)4-E7-E2-E7-E4-C7-C2-C7-C436-9E2-9E4-9C2-9C57-4B20-4B14-5B19-2(5B6-3B10-)5B69-CE2-EC2(2-CE)2-EC6-4(2C2-)2C51-7D10A7D-B7A6G2A6B2-B6AG6-G6AB13(2-7AG6-G7A)2-7AG6-F7A2-2D5AG6-G5A2D2-DA6F6-6FAD3-5GAG6-FA5G4-6AF6-GAB4A4-6AG6-G2(AB4A4-6AF6-F)2(AB)2A4-3B2ABF6-F2BAB2A3-4B3AF6-FAB2ABA3-4B3AF6-FAB3AB4-6BF6-F5BA3-6B2A2F2-2F2AB4A3-7BAGF2-FGAB5A3-9BA2FA2B6A3-B7AB4AB3A4B4-A2B4A7B6AB3-2A2(B3AB2A2B2AB6AB3-BA)B2(2A2B)2AB6AB3-BA5B2A2B2A5B2A2(4-B8A2B8AB)4-B7FA2BA7FB4-BF5-FA2BAF5-FB4-BG5-F5(A2BAG5-GB4-BG5-G)4BG5-GB14(4-AG5-G4BG5-GA)4-AG5-G4BF5-GA4-AF5-F4BF5-FA4-BF5-F4BF5-F2(B4-B8A2B8A)B4-A7BA11B2(4-5A5B10A)4-5B9AB5A3(3-BA4B5A4B6A)3-B20A4-8AB6AB4A4-A4(2B2A)2BA2(4-20A)4-11AB8A4-AB2AB15A2-7D10A7D-B15A6B2-B7A6E7AB2-8AE4CE7AB2-B7A2(C-2C-C8A2-8A)C-CE-C8A2-8A2CE3C2(8A2-8AC-2C-C)8A2-8AC-EC-C8A2-8A3CE2C2(8A2-8AC-2C-C)8A2-8AC-CE-C8A2-8A2CE3C8A2-8AC-2C-C8A2-2D6AC-2C-C6A2D3-F6AC-EC-C6AF4-G6A3CE2C6AG2(4-7AC-2C-C7A)4-7AC-CE-C7A4-7A2CE3C3(7A4-7AC-2C-C)7A4-B6A2E2C2E7A3-B7A6C7A3-B7A2C2E2C7A3-B2A5-6A5-2A3-B2A5-6A5-AB4-4(2A5-6A5-2AB3-)9(2A5-6A5-2A4-)BA5-6A5-AB16(4-2A5-6A5-2A)4-2A5-6A5-AB4-2A5-6A5-2A5(4-20A)4-B19A4(3-B20A)4-20A4-B18AB2-CE20AE3C2AB17A2C2-A18BA4-A18-A2-7D10A7D-B18A3B3(2-3A16-3A)2-4(3A16-2A2B-)8(3A16-3A2-)2DA16-A2D2-DFA16-2AD3-GA16-AG11(4-2A16-2A)4-2A16-AB2(4-4(2A16-2AB3-)2A16-2A)24(4-2A16-2A)4(4-BA16-2A)4(3-B2A16-2A)4-2A16-2A4-BA16-AB2-2C2A16-2A4C2A15CE2A2C2-AB16-BA4-A18-A2-7D10A7D-B18A3B2-B2A16-2AB2-3A16-3A2-3A16-2AB2-4(3A16-2A2B-)5(3A16-3A2-)3A16-2AB2(2-3A16-3A)2-2DA16-A2D3-FA16-AF4-GA16-AG11(4-2A16-2A)4-2(2A16-AB4-4(2A16-2AB3-))6(2A16-2A4-)2(BA16-2A4-)17(2A16-2A4-)BA16-2A3-2BA16-2AB2-2BA16-2AB3-BA4(16-2A3-B2A)4(16-2A4-2A)15CE2A4-AB16-BA4-A18-A2-7D10A7D-B18A3B2(2-3A16-3A)2-3A16-2AB2-4(3A16-2A2B-)8(3A16-3A2-)2DA16-A2D2-DFA16-2AD3-GA16-AG16(4-2A16-2A)4-2A16-AB4-4(2A16-2AB3-)6(2A16-2A4-)BA16-2A3-2BA16-2A3-B17(2A16-2A4-)BA16-AB3-2BA16-A2B2-2BA16-2AB3-8(2A16-2A4-)2A15CEAB4-AB16-BA4-A18-A2-7D10A7D-B18A3B2(2-3A16-3A)2-3A16-2AB2-4(3A16-2A2B-)3A16-3A7(2-2AB16-B2A)2-2DA16-A2D2-DFA16-A2D3-GB16-BG10(4-AB16-BA)6(4-2A16-2A)4-2A16-AB4-4(2A16-2AB3-)6(2A16-2A4-)BA16-2A3-2BA16-2A3-B13(2A16-2A4-)2A16-AB3(4-2A16-2A)4-2A16-AB3-B2A16-A2B2-B2A16-2AB3-5(2A16-2A4-)BA16-AB4-BA16-AB2-2C2A16-2A4C2A15CE2A2C2-AB16-BA4-A18-A2-7D10A7D-B18A3B2(2-3A16-3A)2-3A16-2AB2-3(3A16-2A2B-)B2A16-2A2BC3E16-3EC27-E16-E78-E16-E31-F14-F8-H14-H7-EF14-FE7-F14-F8-H14-H8-F14-F7-EF14-FE7-2(F14-F8-)F14-F7-EF14-FE7-F14-F8-I14-I6-AB16-BA5(4-2A16-2A)4-2A16-AB4-4(2A16-2AB3-)6(2A16-2A4-)2(2A16-2A3-B)2A3(16-2A4-BA)14(16-2A4-2A)2(16-AB4-2A)2(16-2A4-BA)4(16-2A4-2A)16-2A4-BA16-AB2-CE2A16-2AE3C2A15CE2A2C2-2B16-BA4-A18-A2-7D10A7D-B18A3B2(2-3A16-3A)2-B2A16-2AB2-2(3A16-2A2B-)B2A16-2A2B-B2A16-2A2B2C2E16-2E2C27-4(C16-C78-)C16-C31-C14-C6-AB16-BA4-2(2A16-2A4-2A16-AB4-2(2A16-2AB3-))2(2A16-2AB3-)2A16-2A4-2A16-AB7(4-2A16-2A)4-B2(A16-2A3-2B)A13(16-2A4-2A)16-AB3(4-2A16-2A)4-BA16-2A3-2BA16-2AB2-B2A16-2AB3-5(2A16-2A4-)2A15CE2A4-AB16-BA4-A18-A2-7D10A7D-B18A3B2(2-3A16-3A)3(2-3A16-2AB)2(2-B2A16-2AB)-2C2E16-2E2C27-C16-C78-C16-C31-F14-F8-H14-H7-CF14-FC7-F14-F2(8-H14-H)7-CF14-FC7-I14-I2(8-F14-F)7-CF14-FC7-F14-F8-I14-I6-AB16-BA4-2A16-2A4-2A16-AB4-2(2A16-2AB3-)2A16-2A4(4-2A16-AB)10(4-2A16-2A)4-B2(A16-2A3-2B)A16(16-2A4-2A)16-2A4-BA16-AB3-2BA16-A2B2-B2A16-2AB3-5(2A16-2A4-)2A15CE2A4-AB16-BA4-A18-A2-7D10A7D-B18A3B6(2-3A16-3A)2-B2A16-2AB-2C2E16-2E2C27-4(C16-C78-)C16-C31-C14-C6-AB16-BA4-2A16-2A4-2A16-AB4-2(2A16-2AB3-)6(2A16-2A4-)2A16-AB8(4-2A16-2A)4-B2(A16-2A3-2B)A16(16-2A4-2A)16-2A4-BA16-AB3-2BA16-A2B2-B2A16-2AB3-3(2A16-2A4-)BA16-AB2-2C2A16-2A4C2A15CE2A2C2-AB16-BA4-A18-A2-7D10A7D-B18A3B5(2-3A16-3A)2(2-B2A16-2AB)-2C2E16-2E2C27-C16-C78-C16-C31-F14-F8-H14-H7-CF14-FC7-F14-I2(8-H14-H)7-CF14-FC7-2(F14-F8-)F14-F7-CF14-FC7-F14-F8-I14-I6-AB16-BA4-2A16-2A3(4-2A16-AB)16(4-2A16-2A)2(3-B2A16-2A)16(4-2A16-2A)2(4-2A16-AB)4(4-2A16-2A)4-BA16-AB2-CE2A16-2AE3C2A15CE2A2C2-AB16-BA4-A18-A2-7D10A7D-B18A3B2-B2A5(16-3A2-3A)16-3A2-B2A16-2AB-2C2E16-2E2C27-4(C16-C78-)C16-C31-C14-C6-AB16-BA4-2A16-AB22(4-2A16-2A)4-BA17(16-2A4-2A)16-2A4-BA16-2A4-2A16-2A4-BA16-AB2(4-2A16-2A)4-2A15CE2A4-AB16-BA4-A18-A2-7D10A7D-B18A3B2-B2A2(16-3A2-3A)16-2AB2-2(3A16-2A2B-)3A16-3A2-B2A16-2AB-C3E16-3EC27-E16-E78-E16-E31-F23-H22-EF15-E7-I2(23-H)22-EF15-E7-2(F23-)F22-EF15-E7-F23-I14-I6-AB16-BA46(4-2A16-2A)4-2A15CE2A4-AB16-BA4-A18-A2-7D10A7D-B18A3B2-B2A2(16-3A2-3A)16-2AB2-2(3A16-2A2B-)3(3A16-3A2-)7(2AB16-B2A2-)2DA16-A2D2-DFA16-A2D3-GB16-BG10(4-AB16-BA)45(4-2A16-2A)4-BA16-AB2-CE2A16-2AE3C2A15CE2A2C2-AB16-BA4-A18-A2-7D10A7D-B18A3B2(2-3A16-3A)2-3A16-2AB2-2(3A16-2A2B-)10(3A16-3A2-)2DA16-A2D3-FA16-AF4-GA16-AG49(4-2A16-2A)4-2A16-AB4-3(2A16-A2B3-)2A16-2AB3-2A16-AB4-BA16-AB2-2C2A16-2A4C2A15CE2A2C2-AB16-BA4-A18-A2-7D10A7D-B18A3B2(2-3A16-3A)3(2-3A16-2AB)2-3A16-3A2-4(3A16-2A2B-)5(3A16-3A2-)2DA16-A2D2-DFA16-AFD3-GA16-AG3(4-BA16-2A)46(4-2A16-2A)4-2A16-AB4-3(2A16-A2B3-)2A16-2AB3-3(2A16-2A4-)2A15CE2A4-2B16-BA4-A18-A2-7D10A7D-B18A3B5(2-3A16-3A)2-3A16-2AB2-4(3A16-2A2B-)5(3A16-3A2-)2DA16-A2D3-FA16-AF4-GA16-AG4(3-B2A16-2A)45(4-2A16-2A)4-2A16-AB4-3(2A16-A2B3-)2A16-2AB3-BA3(16-2A4-2A)15CEAB4-AB16-BA4-A18-A2-7D10A7D-B18A3B2-B2A5(16-3A2-3A)16-2AB2-4(3A16-2A2B-)5(3A16-3A2-)2DA16-A2D2-DFA16-AFD3-GA16-AG4(3-B2A16-2A)45(4-2A16-2A)4-2A16-AB4-3(2A16-A2B3-)2A16-2AB3-2A16-2A4-BA16-AB2-CE2A16-2A4C2A16E2A2C2-AB16-BA4-A18-A2-7D10A7D-B15A6B5(2-22A)2-21AB2-4(21A2B-)5(22A2-)3D16A3D3-F18AF4-G18AG3(3-B20A)3-B19AB5(4-20A)2(4-B19A9(4-20A))5(4-20A)4-19AB14(4-20A)4-19AB4-3(19A2B3-)20AB3-20A4-B18AB2-2C20AE3C20A2C2-A18BA4-A18-A2-7D10A7D-B15A6B2-22A2-B21A3(2-7A8D7A)2-7A8D6AB2-4(7A8D6A2B-)5(7A8D7A2-)2D5A8D5A2D2-DA18FAD3-20G3(3-B7A4B9A)3-B11AB8A4(4-A5B14A)4-20A4-9AB10A7(4-20A)4-B19A6(4-20A)4-8AB11A2(4-20A)4-5AB6AB7A7(4-20A)4-A7B12A4-A7B10ABA4-A7B11AB4-A7B12A4-20A2(4-7A4B9A)2(4-20A)4(4-10A7B3A)4-20A4-B7A2(4B3A5B4-8A)4B3A5B4-15A5B4-20A4-8AB4AB6A4-A4(2B2A)2BA2(4-20A)4-13AB6A4-8AB5ABAB3A2-24D-22B2-B17ABA2B2-20ABA3(2-22A)2-18A4B2-18A5B-15AB2A5B-18A5B-16AB2A4B-4(22A2-)D20AD2-22D2-2D4(-D)2-4(D-)2D26-5B19-2(5B4-3B12-)5B46-3(7B17-)7B665-3(7B17-)7B47-3B21-3B72-3(7B17-)7B39-3B4-4B13-3B4-2(4B20-)4B53-2(EC2-)CE2-EC2-CE6-4(2C2-)2C52-22D189-3(4B20-)4B1539-4(2C2-)2C6-4(2C2-)2C51-
