model
name = Untitled
revision = 2
size = 6
origin = -y
shell = Outline 0.25
material type = toon, lighting = smooth, deform = 1 1
  colors = B:#E12D39 C:#620042
material type = basic, lighting = smooth, roughness = 0, refractionRatio = 1, side = back
  colors = Outline:#000
voxels
------ ------ ------ ------ ------ ------ 
------ ------ -BBB-- -BBB-- -BBB-- ------ 
------ ------ -BBB-- -BBB-- -BBB-- ------ 
------ ------ -BBB-- -BBBC- -BBBC- ------ 
------ ------ -CCC-- -CCCC- --CCC- ---CC- 
------ ------ ------ ------ ----B- ----BB 
